Workbook
Name BackTest: BackTest!$E$16

Sheet EPL DATA
B2: season | C2: date | D2: league_id | E2: league | F2: team1 | G2: team2 | H2: spi1 | I2: spi2 | J2: prob1 | K2: prob2 | L2: probtie | M2: proj_score1 | N2: proj_score2 | O2: importance1 | P2: importance2 | Q2: score1 | R2: score2 | S2: xg1 | T2: xg2 | U2: nsxg1 | V2: nsxg2 | W2: adj_score1 | X2: adj_score2
B3: 2016 | C3: 42595 | D3: 2411 | E3: Barclays Premier League | F3: Hull City | G3: Leicester City | H3: 53.57 | I3: 66.81 | J3: 0.3459 | K3: 0.3621 | L3: 0.2921 | M3: 1.16 | N3: 1.24 | O3: 38.1 | P3: 22.2 | Q3: 2 | R3: 1 | S3: 0.85 | T3: 2.77 | U3: 0.17 | V3: 1.25 | W3: 2.1 | X3: 1.05
B4: 2016 | C4: 42595 | D4: 2411 | E4: Barclays Premier League | F4: Middlesbrough | G4: Stoke City | H4: 56.32 | I4: 60.35 | J4: 0.438 | K4: 0.2692 | L4: 0.2927 | M4: 1.3 | N4: 1.01 | O4: 33.9 | P4: 32.5 | Q4: 1 | R4: 1 | S4: 1.4 | T4: 0.55 | U4: 1.13 | V4: 1.06 | W4: 1.05 | X4: 1.05
B5: 2016 | C5: 42595 | D5: 2411 | E5: Barclays Premier League | F5: Everton | G5: Tottenham Hotspur | H5: 68.02 | I5: 73.25 | J5: 0.391 | K5: 0.3401 | L5: 0.2689 | M5: 1.47 | N5: 1.38 | O5: 31.9 | P5: 48 | Q5: 1 | R5: 1 | S5: 0.73 | T5: 1.11 | U5: 0.88 | V5: 1.81 | W5: 1.05 | X5: 1.05
B6: 2016 | C6: 42595 | D6: 2411 | E6: Barclays Premier League | F6: Crystal Palace | G6: West Bromwich Albion | H6: 55.19 | I6: 58.66 | J6: 0.4214 | K6: 0.2939 | L6: 0.2847 | M6: 1.35 | N6: 1.14 | O6: 43.6 | P6: 34.6 | Q6: 0 | R6: 1 | S6: 1.11 | T6: 0.68 | U6: 0.84 | V6: 1.6 | W6: 0 | X6: 1.05
B7: 2016 | C7: 42595 | D7: 2411 | E7: Barclays Premier League | F7: Burnley | G7: Swansea City | H7: 58.98 | I7: 59.74 | J7: 0.4482 | K7: 0.2663 | L7: 0.2854 | M7: 1.37 | N7: 1.05 | O7: 36.5 | P7: 29.1 | Q7: 0 | R7: 1 | S7: 1.24 | T7: 1.84 | U7: 1.71 | V7: 1.56 | W7: 0 | X7: 1.05
B8: 2016 | C8: 42595 | D8: 2411 | E8: Barclays Premier League | F8: Southampton | G8: Watford | H8: 69.49 | I8: 59.33 | J8: 0.5759 | K8: 0.1874 | L8: 0.2367 | M8: 1.91 | N8: 1.05 | O8: 34.1 | P8: 30.7 | Q8: 1 | R8: 1 | S8: 1.05 | T8: 0.22 | U8: 1.52 | V8: 0.41 | W8: 1.05 | X8: 1.05
B9: 2016 | C9: 42595 | D9: 2411 | E9: Barclays Premier League | F9: Manchester City | G9: Sunderland | H9: 86.42 | I9: 53.64 | J9: 0.8152 | K9: 0.0525 | L9: 0.1323 | M9: 2.69 | N9: 0.48 | O9: 73 | P9: 27 | Q9: 2 | R9: 1 | S9: 2.14 | T9: 1.25 | U9: 1.81 | V9: 0.92 | W9: 2.1 | X9: 1.05
B10: 2016 | C10: 42596 | D10: 2411 | E10: Barclays Premier League | F10: AFC Bournemouth | G10: Manchester United | H10: 61.57 | I10: 80.49 | J10: 0.2111 | K10: 0.5461 | L10: 0.2428 | M10: 1.15 | N10: 1.78 | O10: 27.9 | P10: 58 | Q10: 1 | R10: 3 | S10: 0.51 | T10: 2.21 | U10: 1.11 | V10: 0.88 | W10: 1.05 | X10: 3.15
B11: 2016 | C11: 42596 | D11: 2411 | E11: Barclays Premier League | F11: Arsenal | G11: Liverpool | H11: 82.55 | I11: 77.44 | J11: 0.5551 | K11: 0.2115 | L11: 0.2334 | M11: 1.91 | N11: 1.21 | O11: 62.7 | P11: 63.9 | Q11: 3 | R11: 4 | S11: 1.14 | T11: 1.84 | U11: 1.19 | V11: 1.49 | W11: 3.15 | X11: 4.2
B12: 2016 | C12: 42597 | D12: 2411 | E12: Barclays Premier League | F12: Chelsea | G12: West Ham United | H12: 80.7 | I12: 63.27 | J12: 0.6908 | K12: 0.1177 | L12: 0.1915 | M12: 2.23 | N12: 0.91 | O12: 67.7 | P12: 25.5 | Q12: 2 | R12: 1 | S12: 1.55 | T12: 0.55 | U12: 1.76 | V12: 0.75 | W12: 2.1 | X12: 1.05
B13: 2016 | C13: 42601 | D13: 2411 | E13: Barclays Premier League | F13: Manchester United | G13: Southampton | H13: 81.05 | I13: 69.22 | J13: 0.6197 | K13: 0.1494 | L13: 0.2309 | M13: 1.85 | N13: 0.87 | O13: 61.8 | P13: 41.6 | Q13: 2 | R13: 0 | S13: 1.37 | T13: 0.7 | U13: 1.59 | V13: 1.69 | W13: 2.1 | X13: 0
B14: 2016 | C14: 42602 | D14: 2411 | E14: Barclays Premier League | F14: Stoke City | G14: Manchester City | H14: 60.42 | I14: 85.71 | J14: 0.1278 | K14: 0.672 | L14: 0.2002 | M14: 0.99 | N14: 1.98 | O14: 28.9 | P14: 67 | Q14: 1 | R14: 4 | S14: 1.38 | T14: 2.26 | U14: 0.83 | V14: 2.05 | W14: 1.05 | X14: 3.27
... B152: 2016 | C152: 42715 | D152: 2411 | E152: Barclays Premier League | F152: Liverpool | G152: West Ham United | H152: 82.14 | I152: 59.9 | J152: 0.7453 | K152: 0.0959 | L152: 0.1588 | M152: 2.71 | N152: 0.86 | O152: 59.6 | P152: 31.7 | Q152: 2 | R152: 2 | S152: 1.93 | T152: 0.71 | U152: 3.39 | V152: 0.28 | W152: 2.1 | X152: 2.1
B153: 2016 | C153: 42717 | D153: 2411 | E153: Barclays Premier League | F153: AFC Bournemouth | G153: Leicester City | H153: 62.47 | I153: 63.24 | J153: 0.4549 | K153: 0.2909 | L153: 0.2542 | M153: 1.71 | N153: 1.4 | Q153: 1 | R153: 0 | S153: 0.62 | T153: 1.49 | U153: 0.83 | V153: 2.43 | W153: 1.05 | X153: 0
B154: 2016 | C154: 42717 | D154: 2411 | E154: Barclays Premier League | F154: Everton | G154: Arsenal | H154: 65.92 | I154: 85.11 | J154: 0.1743 | K154: 0.6144 | L154: 0.2112 | M154: 1.24 | N154: 2 | Q154: 2 | R154: 1 | S154: 1.44 | T154: 1.5 | U154: 1.47 | V154: 1.89 | W154: 2.1 | X154: 1.05
B155: 2016 | C155: 42718 | D155: 2411 | E155: Barclays Premier League | F155: West Ham United | G155: Burnley | H155: 60.48 | I155: 54.41 | J155: 0.521 | K155: 0.2248 | L155: 0.2541 | M155: 1.74 | N155: 1.11 | Q155: 1 | R155: 0 | S155: 2.21 | T155: 1.06 | U155: 1.6 | V155: 1.39 | W155: 1.05 | X155: 0
B156: 2016 | C156: 42718 | D156: 2411 | E156: Barclays Premier League | F156: Middlesbrough | G156: Liverpool | H156: 55.14 | I156: 81.74 | J156: 0.1692 | K156: 0.604 | L156: 0.2268 | M156: 1.02 | N156: 1.82 | Q156: 0 | R156: 3 | S156: 0.26 | T156: 2.15 | U156: 0.46 | V156: 2.08 | W156: 0 | X156: 3.15
B157: 2016 | C157: 42718 | D157: 2411 | E157: Barclays Premier League | F157: Sunderland | G157: Chelsea | H157: 49.97 | I157: 86.3 | J157: 0.0736 | K157: 0.7687 | L157: 0.1577 | M157: 0.83 | N157: 2.26 | Q157: 0 | R157: 1 | S157: 0.55 | T157: 1.08 | U157: 1 | V157: 2.43 | W157: 0 | X157: 1.05
B158: 2016 | C158: 42718 | D158: 2411 | E158: Barclays Premier League | F158: Crystal Palace | G158: Manchester United | H158: 59.76 | I158: 79.33 | J158: 0.2144 | K158: 0.5447 | L158: 0.2409 | M158: 1.18 | N158: 1.88 | Q158: 1 | R158: 2 | S158: 0.7 | T158: 1.37 | U158: 0.76 | V158: 2.22 | W158: 1.05 | X158: 2.1
B159: 2016 | C159: 42718 | D159: 2411 | E159: Barclays Premier League | F159: Stoke City | G159: Southampton | H159: 62.19 | I159: 68.57 | J159: 0.3852 | K159: 0.3158 | L159: 0.2989 | M159: 1.19 | N159: 1.11 | Q159: 0 | R159: 0 | S159: 0.34 | T159: 0.71 | U159: 0.52 | V159: 2.33 | W159: 0 | X159: 0
B160: 2016 | C160: 42718 | D160: 2411 | E160: Barclays Premier League | F160: Tottenham Hotspur | G160: Hull City | H160: 77.63 | I160: 43.95 | J160: 0.7545 | K160: 0.0671 | L160: 0.1783 | M160: 2.3 | N160: 0.36 | Q160: 3 | R160: 0 | S160: 2.64 | T160: 0.73 | U160: 2.53 | V160: 1.27 | W160: 3.08 | X160: 0
B161: 2016 | C161: 42718 | D161: 2411 | E161: Barclays Premier League | F161: Manchester City | G161: Watford | H161: 85.04 | I161: 60.14 | J161: 0.7818 | K161: 0.0742 | L161: 0.144 | M161: 2.74 | N161: 0.72 | Q161: 2 | R161: 0 | S161: 1.72 | T161: 0.57 | U161: 2.28 | V161: 0.5 | W161: 1.7 | X161: 0
B162: 2016 | C162: 42718 | D162: 2411 | E162: Barclays Premier League | F162: West Bromwich Albion | G162: Swansea City | H162: 62.24 | I162: 58.06 | J162: 0.4963 | K162: 0.2414 | L162: 0.2623 | M162: 1.66 | N162: 1.11 | Q162: 3 | R162: 1 | S162: 1.88 | T162: 1.46 | U162: 1.24 | V162: 1.58 | W162: 3.15 | X162: 1.05
B163: 2016 | C163: 42721 | D163: 2411 | E163: Barclays Premier League | F163: Crystal Palace | G163: Chelsea | H163: 59.3 | I163: 86.27 | J163: 0.1037 | K163: 0.7218 | L163: 0.1745 | M163: 1.04 | N163: 2.28 | O163: 32.9 | P163: 97.2 | Q163: 0 | R163: 1 | S163: 0.42 | T163: 0.8 | U163: 1.06 | V163: 1.85 | W163: 0 | X163: 1.05
B164: 2016 | C164: 42721 | D164: 2411 | E164: Barclays Premier League | F164: Middlesbrough | G164: Swansea City | H164: 53.26 | I164: 57.55 | J164: 0.436 | K164: 0.2815 | L164: 0.2825 | M164: 1.4 | N164: 1.12 | O164: 49.6 | P164: 53.2 | Q164: 3 | R164: 0 | S164: 1.77 | T164: 0.84 | U164: 0.79 | V164: 2.02 | W164: 3.15 | X164: 0
B165: 2016 | C165: 42721 | D165: 2411 | E165: Barclays Premier League | F165: Sunderland | G165: Watford | H165: 49.82 | I165: 59.87 | J165: 0.3806 | K165: 0.3425 | L165: 0.2769 | M165: 1.37 | N165: 1.35 | O165: 48.1 | P165: 15.1 | Q165: 1 | R165: 0 | S165: 1.23 | T165: 0.72 | U165: 1.32 | V165: 1.32 | W165: 1.05 | X165: 0
B166: 2016 | C166: 42721 | D166: 2411 | E166: Barclays Premier League | F166: West Ham United | G166: Hull City | H166: 60.78 | I166: 43.51 | J166: 0.6003 | K166: 0.1633 | L166: 0.2364 | M166: 1.9 | N166: 0.88 | O166: 35.7 | P166: 48 | Q166: 1 | R166: 0 | S166: 2.12 | T166: 1.19 | U166: 1.19 | V166: 1.49 | W166: 1.05 | X166: 0
B167: 2016 | C167: 42721 | D167: 2411 | E167: Barclays Premier League | F167: Stoke City | G167: Leicester City | H167: 61.26 | I167: 63.64 | J167: 0.4287 | K167: 0.2884 | L167: 0.2829 | M167: 1.39 | N167: 1.13 | O167: 20.8 | P167: 22.1 | Q167: 2 | R167: 2 | S167: 2.4 | T167: 1.39 | U167: 1.81 | V167: 1.48 | W167: 2.1 | X167: 2.1
B168: 2016 | C168: 42721 | D168: 2411 | E168: Barclays Premier League | F168: West Bromwich Albion | G168: Manchester United | H168: 62.74 | I168: 79.64 | J168: 0.2434 | K168: 0.4799 | L168: 0.2767 | M168: 1.02 | N168: 1.46 | O168: 4.9 | P168: 56.3 | Q168: 0 | R168: 2 | S168: 0.67 | T168: 0.88 | U168: 0.84 | V168: 1.24 | W168: 0 | X168: 2.1
B169: 2016 | C169: 42722 | D169: 2411 | E169: Barclays Premier League | F169: AFC Bournemouth | G169: Southampton | H169: 62.01 | I169: 69.32 | J169: 0.3714 | K169: 0.3446 | L169: 0.284 | M169: 1.3 | N169: 1.29 | O169: 11.1 | P169: 4 | Q169: 1 | R169: 3 | S169: 0.57 | T169: 1.36 | U169: 1.38 | V169: 1.59 | W169: 1.05 | X169: 2.76
B170: 2016 | C170: 42722 | D170: 2411 | E170: Barclays Premier League | F170: Manchester City | G170: Arsenal | H170: 85.1 | I170: 84.33 | J170: 0.4823 | K170: 0.2837 | L170: 0.234 | M170: 1.92 | N170: 1.49 | O170: 51.3 | P170: 60.1 | Q170: 2 | R170: 1 | S170: 1.73 | T170: 0.66 | U170: 1.94 | V170: 0.88 | W170: 2.1 | X170: 1.05
B171: 2016 | C171: 42722 | D171: 2411 | E171: Barclays Premier League | F171: Tottenham Hotspur | G171: Burnley | H171: 78.01 | I171: 54.1 | J171: 0.7138 | K171: 0.0882 | L171: 0.198 | M171: 2.04 | N171: 0.59 | O171: 66.7 | P171: 31.6 | Q171: 2 | R171: 1 | S171: 1.68 | T171: 1.43 | U171: 1.6 | V171: 1.07 | W171: 2.1 | X171: 1.05
B172: 2016 | C172: 42723 | D172: 2411 | E172: Barclays Premier League | F172: Everton | G172: Liverpool | H172: 67.04 | I172: 83.07 | J172: 0.2254 | K172: 0.5437 | L172: 0.2309 | M172: 1.33 | N172: 1.88 | O172: 8.3 | P172: 55.6 | Q172: 0 | R172: 1 | S172: 0.46 | T172: 2.42 | U172: 0.48 | V172: 1.87 | W172: 0 | X172: 1.05
B173: 2016 | C173: 42730 | D173: 2411 | E173: Barclays Premier League | F173: Watford | G173: Crystal Palace | H173: 59.24 | I173: 59.06 | J173: 0.4597 | K173: 0.2826 | L173: 0.2577 | M173: 1.7 | N173: 1.33 | O173: 21.4 | P173: 40.6 | Q173: 1 | R173: 1 | S173: 1 | T173: 1.48 | U173: 1.14 | V173: 0.54 | W173: 1.05 | X173: 1.05
B174: 2016 | C174: 42730 | D174: 2411 | E174: Barclays Premier League | F174: Swansea City | G174: West Ham United | H174: 56.09 | I174: 60.53 | J174: 0.4211 | K174: 0.3226 | L174: 0.2563 | M174: 1.67 | N174: 1.53 | O174: 48.4 | P174: 23.6 | Q174: 1 | R174: 4 | S174: 0.93 | T174: 3.16 | U174: 1.5 | V174: 1.38 | W174: 1.05 | X174: 3.51
... B192: 2016 | C192: 42736 | D192: 2411 | E192: Barclays Premier League | F192: Arsenal | G192: Crystal Palace | H192: 84.22 | I192: 59.4 | J192: 0.7769 | K192: 0.0775 | L192: 0.1456 | M192: 2.77 | N192: 0.75 | O192: 71.2 | P192: 29.7 | Q192: 2 | R192: 0 | S192: 1.8 | T192: 0.58 | U192: 2.58 | V192: 0.73 | W192: 2.1 | X192: 0
B193: 2016 | C193: 42737 | D193: 2411 | E193: Barclays Premier League | F193: Middlesbrough | G193: Leicester City | H193: 54.25 | I193: 61.85 | J193: 0.4065 | K193: 0.2991 | L193: 0.2944 | M193: 1.24 | N193: 1.09 | Q193: 0 | R193: 0 | S193: 0.91 | T193: 0.56 | U193: 1 | V193: 1.45 | W193: 0 | X193: 0
B194: 2016 | C194: 42737 | D194: 2411 | E194: Barclays Premier League | F194: Everton | G194: Southampton | H194: 66.81 | I194: 67.11 | J194: 0.4521 | K194: 0.2605 | L194: 0.2874 | M194: 1.36 | N194: 1.03 | Q194: 3 | R194: 0 | S194: 2.28 | T194: 0.74 | U194: 2.03 | V194: 1.51 | W194: 2.39 | X194: 0
B195: 2016 | C195: 42737 | D195: 2411 | E195: Barclays Premier League | F195: Manchester City | G195: Burnley | H195: 85.57 | I195: 57.33 | J195: 0.7931 | K195: 0.0588 | L195: 0.1481 | M195: 2.52 | N195: 0.47 | Q195: 2 | R195: 1 | S195: 0.74 | T195: 0.92 | U195: 1.55 | V195: 1.43 | W195: 2.1 | X195: 1.05
...

Sheet Bet365 Odds
E7: Home | F7: Away | G7: Max H | H7: Max D | I7: Max A | L7: man city | M7: man city | N7: =L7=M7 -> TRUE
D8: =E8&F8 -> LiverpoolNorwich City | E8: Liverpool | F8: Norwich City | G8: 1.16 | H8: 10 | I8: 23
D9: =E9&F9 -> West Ham UnitedManchester City | E9: West Ham United | F9: Manchester City | G9: 13 | H9: 6.75 | I9: 1.29
D10: =E10&F10 -> AFC BournemouthSheffield United | E10: AFC Bournemouth | F10: Sheffield United | G10: 2.06 | H10: 3.65 | I10: 4
D11: =E11&F11 -> BurnleySouthampton | E11: Burnley | F11: Southampton | G11: 2.8 | H11: 3.33 | I11: 2.85
D12: =E12&F12 -> Crystal PalaceEverton | E12: Crystal Palace | F12: Everton | G12: 3.21 | H12: 3.4 | I12: 2.52
D13: =E13&F13 -> WatfordBrighton and Hove Albion | E13: Watford | F13: Brighton and Hove Albion | G13: 2 | H13: 3.5 | I13: 4.6
D14: =E14&F14 -> Tottenham HotspurAston Villa | E14: Tottenham Hotspur | F14: Aston Villa | G14: 1.33 | H14: 5.95 | I14: 12
D15: =E15&F15 -> Leicester CityWolverhampton | E15: Leicester City | F15: Wolverhampton | G15: 2.29 | H15: 3.38 | I15: 3.66
D16: =E16&F16 -> NewcastleArsenal | E16: Newcastle | F16: Arsenal | G16: 4.7 | H16: 4 | I16: 1.83
D17: =E17&F17 -> Manchester UnitedChelsea | E17: Manchester United | F17: Chelsea | G17: 2.28 | H17: 3.43 | I17: 3.63
D18: =E18&F18 -> ArsenalBurnley | E18: Arsenal | F18: Burnley | G18: 1.36 | H18: 5.75 | I18: 11
D19: =E19&F19 -> Aston VillaAFC Bournemouth | E19: Aston Villa | F19: AFC Bournemouth | G19: 2.42 | H19: 3.64 | I19: 3.2
... D380: =E380&F380 -> ChelseaWolverhampton | E380: Chelsea | F380: Wolverhampton | G380: 1.9 | H380: 3.92 | I380: 4.55
D381: =E381&F381 -> Crystal PalaceTottenham Hotspur | E381: Crystal Palace | F381: Tottenham Hotspur | G381: 6.75 | H381: 4.45 | I381: 1.6 | L381: =MIN(H8:H387) -> 3.1
D382: =E382&F382 -> EvertonAFC Bournemouth | E382: Everton | F382: AFC Bournemouth | G382: 2.33 | H382: 4.1 | I382: 3.15
D383: =E383&F383 -> Leicester CityManchester United | E383: Leicester City | F383: Manchester United | G383: 3.36 | H383: 4.54 | I383: 2.35
D384: =E384&F384 -> Manchester CityNorwich City | E384: Manchester City | F384: Norwich City | G384: 1.1 | H384: 15.25 | I384: 41
D385: =E385&F385 -> NewcastleLiverpool | E385: Newcastle | F385: Liverpool | G385: 8.2 | H385: 5.4 | I385: 1.45
D386: =E386&F386 -> SouthamptonSheffield United | E386: Southampton | F386: Sheffield United | G386: 2.25 | H386: 3.6 | I386: 3.56
D387: =E387&F387 -> West Ham UnitedAston Villa | E387: West Ham United | F387: Aston Villa | G387: 3.2 | H387: 3.82 | I387: 2.36

Sheet Calculator
H4: Season 2018 | I4: =1-I5 -> 0.00069252078
H5: Season 2019 | I5: =1-(1-($Y$63/$Y$94))^2 -> 0.99930748
G8: Combination of seasons
G10: HGS | H10: HGC | I10: AGS | J10: AGC | K10: HXGS | L10: HXGC | M10: AXGS | N10: AXGC | O10: Home AS | P10: Home DW | Q10: Away AS | R10: Away DW | S10: XHome AS | T10: XHome DW | U10: XAway AS | V10: XAway DW
F11: AFC Bournemouth | G11: =VLOOKUP($F11,$F$44:$X$63,2,FALSE) * $I$5 + VLOOKUP($F11,$F$75:$X$94,2,FALSE)*$I$4 -> 1.1581863 | H11: =VLOOKUP($F11,$F$44:$X$63,3,FALSE) * $I$5 + VLOOKUP($F11,$F$75:$X$94,3,FALSE)*$I$4 -> 1.5787651 | I11: =VLOOKUP($F11,$F$44:$X$63,4,FALSE) * $I$5 + VLOOKUP($F11,$F$75:$X$94,4,FALSE)*$I$4 -> 0.83370389 | J11: =VLOOKUP($F11,$F$44:$X$63,5,FALSE) * $I$5 + VLOOKUP($F11,$F$75:$X$94,5,FALSE)*$I$4 -> 1.889221 | K11: =VLOOKUP($F11,$F$44:$X$63,6,FALSE) * $I$5 + VLOOKUP($F11,$F$75:$X$94,6,FALSE)*$I$4 -> 1.3097478 | L11: =VLOOKUP($F11,$F$44:$X$63,7,FALSE) * $I$5 + VLOOKUP($F11,$F$75:$X$94,7,FALSE)*$I$4 -> 1.6329622 | M11: =VLOOKUP($F11,$F$44:$X$63,8,FALSE) * $I$5 + VLOOKUP($F11,$F$75:$X$94,8,FALSE)*$I$4 -> 1.1346841 | N11: =VLOOKUP($F11,$F$44:$X$63,9,FALSE) * $I$5 + VLOOKUP($F11,$F$75:$X$94,9,FALSE)*$I$4 -> 1.7755962 | O11: =G11/$B$13 -> 0.76775166 | P11: =H11/$B$15 -> 1.3198214 | Q11: =I11/$B$17 -> 0.69889697 | R11: =J11/$B$19 -> 1.2532553 | S11: =K11/$B$23 -> 0.82108651 | T11: =L11/$B$25 -> 1.1934161 | U11: =M11/$B$27 -> 0.83078232 | V11: =N11/$B$29 -> 1.1135372
B12: Home Average goal scored | F12: Arsenal | G12: =VLOOKUP($F12,$F$44:$X$63,2,FALSE) * $I$5 + VLOOKUP($F12,$F$75:$X$94,2,FALSE)*$I$4 -> 1.8335945 | H12: =VLOOKUP($F12,$F$44:$X$63,3,FALSE) * $I$5 + VLOOKUP($F12,$F$75:$X$94,3,FALSE)*$I$4 -> 1.221959 | I12: =VLOOKUP($F12,$F$44:$X$63,4,FALSE) * $I$5 + VLOOKUP($F12,$F$75:$X$94,4,FALSE)*$I$4 -> 1.0530325 | J12: =VLOOKUP($F12,$F$44:$X$63,5,FALSE) * $I$5 + VLOOKUP($F12,$F$75:$X$94,5,FALSE)*$I$4 -> 1.2635588 | K12: =VLOOKUP($F12,$F$44:$X$63,6,FALSE) * $I$5 + VLOOKUP($F12,$F$75:$X$94,6,FALSE)*$I$4 -> 1.4825239 | L12: =VLOOKUP($F12,$F$44:$X$63,7,FALSE) * $I$5 + VLOOKUP($F12,$F$75:$X$94,7,FALSE)*$I$4 -> 1.5820742 | M12: =VLOOKUP($F12,$F$44:$X$63,8,FALSE) * $I$5 + VLOOKUP($F12,$F$75:$X$94,8,FALSE)*$I$4 -> 1.2574785 | N12: =VLOOKUP($F12,$F$44:$X$63,9,FALSE) * $I$5 + VLOOKUP($F12,$F$75:$X$94,9,FALSE)*$I$4 -> 1.4654199 | O12: =G12/$B$13 -> 1.2154739 | P12: =H12/$B$15 -> 1.0215374 | Q12: =I12/$B$17 -> 0.88276094 | R12: =J12/$B$19 -> 0.8382089 | S12: =K12/$B$23 -> 0.92940063 | T12: =L12/$B$25 -> 1.1562257 | U12: =M12/$B$27 -> 0.92068875 | V12: =N12/$B$29 -> 0.91901499
B13: =SUM(G11:G30)/20 -> 1.5085429 | F13: Brighton and Hove Albion | G13: =VLOOKUP($F13,$F$44:$X$63,2,FALSE) * $I$5 + VLOOKUP($F13,$F$75:$X$94,2,FALSE)*$I$4 -> 1.0525951 | H13: =VLOOKUP($F13,$F$44:$X$63,3,FALSE) * $I$5 + VLOOKUP($F13,$F$75:$X$94,3,FALSE)*$I$4 -> 1.4210891 | I13: =VLOOKUP($F13,$F$44:$X$63,4,FALSE) * $I$5 + VLOOKUP($F13,$F$75:$X$94,4,FALSE)*$I$4 -> 0.94437357 | J13: =VLOOKUP($F13,$F$44:$X$63,5,FALSE) * $I$5 + VLOOKUP($F13,$F$75:$X$94,5,FALSE)*$I$4 -> 1.4446105 | K13: =VLOOKUP($F13,$F$44:$X$63,6,FALSE) * $I$5 + VLOOKUP($F13,$F$75:$X$94,6,FALSE)*$I$4 -> 1.3251148 | L13: =VLOOKUP($F13,$F$44:$X$63,7,FALSE) * $I$5 + VLOOKUP($F13,$F$75:$X$94,7,FALSE)*$I$4 -> 1.4736153 | M13: =VLOOKUP($F13,$F$44:$X$63,8,FALSE) * $I$5 + VLOOKUP($F13,$F$75:$X$94,8,FALSE)*$I$4 -> 1.2564219 | N13: =VLOOKUP($F13,$F$44:$X$63,9,FALSE) * $I$5 + VLOOKUP($F13,$F$75:$X$94,9,FALSE)*$I$4 -> 1.674671 | O13: =G13/$B$13 -> 0.69775617 | P13: =H13/$B$15 -> 1.1880069 | Q13: =I13/$B$17 -> 0.79167176 | R13: =J13/$B$19 -> 0.95831341 | S13: =K13/$B$23 -> 0.83072017 | T13: =L13/$B$25 -> 1.0769608 | U13: =M13/$B$27 -> 0.91991511 | V13: =N13/$B$29 -> 1.0502435
B14: Home average goal conceded | F14: Burnley | G14: =VLOOKUP($F14,$F$44:$X$63,2,FALSE) * $I$5 + VLOOKUP($F14,$F$75:$X$94,2,FALSE)*$I$4 -> 1.2777677 | H14: =VLOOKUP($F14,$F$44:$X$63,3,FALSE) * $I$5 + VLOOKUP($F14,$F$75:$X$94,3,FALSE)*$I$4 -> 1.1670251 | I14: =VLOOKUP($F14,$F$44:$X$63,4,FALSE) * $I$5 + VLOOKUP($F14,$F$75:$X$94,4,FALSE)*$I$4 -> 1.0000729 | J14: =VLOOKUP($F14,$F$44:$X$63,5,FALSE) * $I$5 + VLOOKUP($F14,$F$75:$X$94,5,FALSE)*$I$4 -> 1.4213807 | K14: =VLOOKUP($F14,$F$44:$X$63,6,FALSE) * $I$5 + VLOOKUP($F14,$F$75:$X$94,6,FALSE)*$I$4 -> 1.6642496 | L14: =VLOOKUP($F14,$F$44:$X$63,7,FALSE) * $I$5 + VLOOKUP($F14,$F$75:$X$94,7,FALSE)*$I$4 -> 1.406779 | M14: =VLOOKUP($F14,$F$44:$X$63,8,FALSE) * $I$5 + VLOOKUP($F14,$F$75:$X$94,8,FALSE)*$I$4 -> 1.0279345 | N14: =VLOOKUP($F14,$F$44:$X$63,9,FALSE) * $I$5 + VLOOKUP($F14,$F$75:$X$94,9,FALSE)*$I$4 -> 1.5839324 | O14: =G14/$B$13 -> 0.84702108 | P14: =H14/$B$15 -> 0.9756136 | Q14: =I14/$B$17 -> 0.8383647 | R14: =J14/$B$19 -> 0.94290341 | S14: =K14/$B$23 -> 1.0433253 | T14: =L14/$B$25 -> 1.0281149 | U14: =M14/$B$27 -> 0.75262337 | V14: =N14/$B$29 -> 0.99333826
B15: =SUM(H11:H30)/20 -> 1.196196 | F15: Aston Villa | G15: =VLOOKUP($F15,$F$44:$X$63,2,FALSE) -> 1.1578947 | H15: =VLOOKUP($F15,$F$44:$X$63,3,FALSE) -> 1.5789474 | I15: =VLOOKUP($F15,$F$44:$X$63,4,FALSE) -> 1 | J15: =VLOOKUP($F15,$F$44:$X$63,5,FALSE) -> 2 | K15: =VLOOKUP($F15,$F$44:$X$63,6,FALSE) -> 1.3542105 | L15: =VLOOKUP($F15,$F$44:$X$63,7,FALSE) -> 1.8184211 | M15: =VLOOKUP($F15,$F$44:$X$63,8,FALSE) -> 1.1483333 | N15: =VLOOKUP($F15,$F$44:$X$63,9,FALSE) -> 2.1072222 | O15: =G15/$B$13 -> 0.76755837 | P15: =H15/$B$15 -> 1.3199738 | Q15: =I15/$B$17 -> 0.83830359 | R15: =J15/$B$19 -> 1.326743 | S15: =K15/$B$23 -> 0.8489604 | T15: =L15/$B$25 -> 1.3289549 | U15: =M15/$B$27 -> 0.84077588 | V15: =N15/$B$29 -> 1.3215112
B16: Away Average goal scored | F16: Chelsea | G16: =VLOOKUP($F16,$F$44:$X$63,2,FALSE) * $I$5 + VLOOKUP($F16,$F$75:$X$94,2,FALSE)*$I$4 -> 1.5558998 | H16: =VLOOKUP($F16,$F$44:$X$63,3,FALSE) * $I$5 + VLOOKUP($F16,$F$75:$X$94,3,FALSE)*$I$4 -> 0.8887107 | I16: =VLOOKUP($F16,$F$44:$X$63,4,FALSE) * $I$5 + VLOOKUP($F16,$F$75:$X$94,4,FALSE)*$I$4 -> 2.0520849 | J16: =VLOOKUP($F16,$F$44:$X$63,5,FALSE) * $I$5 + VLOOKUP($F16,$F$75:$X$94,5,FALSE)*$I$4 -> 1.9995991 | K16: =VLOOKUP($F16,$F$44:$X$63,6,FALSE) * $I$5 + VLOOKUP($F16,$F$75:$X$94,6,FALSE)*$I$4 -> 2.5217888 | L16: =VLOOKUP($F16,$F$44:$X$63,7,FALSE) * $I$5 + VLOOKUP($F16,$F$75:$X$94,7,FALSE)*$I$4 -> 0.7827908 | M16: =VLOOKUP($F16,$F$44:$X$63,8,FALSE) * $I$5 + VLOOKUP($F16,$F$75:$X$94,8,FALSE)*$I$4 -> 1.7063118 | N16: =VLOOKUP($F16,$F$44:$X$63,9,FALSE) * $I$5 + VLOOKUP($F16,$F$75:$X$94,9,FALSE)*$I$4 -> 1.4678302 | O16: =G16/$B$13 -> 1.0313925 | P16: =H16/$B$15 -> 0.74294739 | Q16: =I16/$B$17 -> 1.7202701 | R16: =J16/$B$19 -> 1.326477 | S16: =K16/$B$23 -> 1.5809202 | T16: =L16/$B$25 -> 0.57208623 | U16: =M16/$B$27 -> 1.2493113 | V16: =N16/$B$29 -> 0.92052659
B17: =SUM(I11:I30)/20 -> 1.1928853 | F17: Crystal Palace | G17: =VLOOKUP($F17,$F$44:$X$63,2,FALSE) * $I$5 + VLOOKUP($F17,$F$75:$X$94,2,FALSE)*$I$4 -> 0.77793167 | H17: =VLOOKUP($F17,$F$44:$X$63,3,FALSE) * $I$5 + VLOOKUP($F17,$F$75:$X$94,3,FALSE)*$I$4 -> 1.0556629 | I17: =VLOOKUP($F17,$F$44:$X$63,4,FALSE) * $I$5 + VLOOKUP($F17,$F$75:$X$94,4,FALSE)*$I$4 -> 0.84268844 | J17: =VLOOKUP($F17,$F$44:$X$63,5,FALSE) * $I$5 + VLOOKUP($F17,$F$75:$X$94,5,FALSE)*$I$4 -> 1.5789474 | K17: =VLOOKUP($F17,$F$44:$X$63,6,FALSE) * $I$5 + VLOOKUP($F17,$F$75:$X$94,6,FALSE)*$I$4 -> 1.0552579 | L17: =VLOOKUP($F17,$F$44:$X$63,7,FALSE) * $I$5 + VLOOKUP($F17,$F$75:$X$94,7,FALSE)*$I$4 -> 1.2966872 | M17: =VLOOKUP($F17,$F$44:$X$63,8,FALSE) * $I$5 + VLOOKUP($F17,$F$75:$X$94,8,FALSE)*$I$4 -> 0.91121957 | N17: =VLOOKUP($F17,$F$44:$X$63,9,FALSE) * $I$5 + VLOOKUP($F17,$F$75:$X$94,9,FALSE)*$I$4 -> 1.9391832 | O17: =G17/$B$13 -> 0.51568415 | P17: =H17/$B$15 -> 0.88251664 | Q17: =I17/$B$17 -> 0.70642875 | R17: =J17/$B$19 -> 1.0474287 | S17: =K17/$B$23 -> 0.6615457 | T17: =L17/$B$25 -> 0.94765663 | U17: =M17/$B$27 -> 0.66716815 | V17: =N17/$B$29 -> 1.2161282
B18: Away average goal conceded | F18: Everton | G18: =VLOOKUP($F18,$F$44:$X$63,2,FALSE) * $I$5 + VLOOKUP($F18,$F$75:$X$94,2,FALSE)*$I$4 -> 1.2779863 | H18: =VLOOKUP($F18,$F$44:$X$63,3,FALSE) * $I$5 + VLOOKUP($F18,$F$75:$X$94,3,FALSE)*$I$4 -> 1.0000729 | I18: =VLOOKUP($F18,$F$44:$X$63,4,FALSE) * $I$5 + VLOOKUP($F18,$F$75:$X$94,4,FALSE)*$I$4 -> 1.0527774 | J18: =VLOOKUP($F18,$F$44:$X$63,5,FALSE) * $I$5 + VLOOKUP($F18,$F$75:$X$94,5,FALSE)*$I$4 -> 1.8417408 | K18: =VLOOKUP($F18,$F$44:$X$63,6,FALSE) * $I$5 + VLOOKUP($F18,$F$75:$X$94,6,FALSE)*$I$4 -> 1.4345908 | L18: =VLOOKUP($F18,$F$44:$X$63,7,FALSE) * $I$5 + VLOOKUP($F18,$F$75:$X$94,7,FALSE)*$I$4 -> 1.2466569 | M18: =VLOOKUP($F18,$F$44:$X$63,8,FALSE) * $I$5 + VLOOKUP($F18,$F$75:$X$94,8,FALSE)*$I$4 -> 1.339411 | N18: =VLOOKUP($F18,$F$44:$X$63,9,FALSE) * $I$5 + VLOOKUP($F18,$F$75:$X$94,9,FALSE)*$I$4 -> 1.3642269 | O18: =G18/$B$13 -> 0.84716605 | P18: =H18/$B$15 -> 0.83604434 | Q18: =I18/$B$17 -> 0.88254705 | R18: =J18/$B$19 -> 1.2217583 | S18: =K18/$B$23 -> 0.89935114 | T18: =L18/$B$25 -> 0.91109307 | U18: =M18/$B$27 -> 0.98067732 | V18: =N18/$B$29 -> 0.85555342
B19: =SUM(J11:J30)/20 -> 1.507451 | F19: Norwich City | G19: =VLOOKUP($F19,$F$44:$X$63,2,FALSE) -> 1 | H19: =VLOOKUP($F19,$F$44:$X$63,3,FALSE) -> 1.9473684 | I19: =VLOOKUP($F19,$F$44:$X$63,4,FALSE) -> 0.38888889 | J19: =VLOOKUP($F19,$F$44:$X$63,5,FALSE) -> 1.8333333 | K19: =VLOOKUP($F19,$F$44:$X$63,6,FALSE) -> 0.96473684 | L19: =VLOOKUP($F19,$F$44:$X$63,7,FALSE) -> 1.9373684 | M19: =VLOOKUP($F19,$F$44:$X$63,8,FALSE) -> 0.96277778 | N19: =VLOOKUP($F19,$F$44:$X$63,9,FALSE) -> 1.8144444 | O19: =G19/$B$13 -> 0.66289132 | P19: =H19/$B$15 -> 1.6279677 | Q19: =I19/$B$17 -> 0.32600695 | R19: =J19/$B$19 -> 1.2161811 | S19: =K19/$B$23 -> 0.60479767 | T19: =L19/$B$25 -> 1.4158851 | U19: =M19/$B$27 -> 0.70491756 | V19: =N19/$B$29 -> 1.1379002
F20: Sheffield United | G20: =VLOOKUP($F20,$F$44:$X$63,2,FALSE) -> 1.2631579 | H20: =VLOOKUP($F20,$F$44:$X$63,3,FALSE) -> 0.78947368 | I20: =VLOOKUP($F20,$F$44:$X$63,4,FALSE) -> 0.77777778 | J20: =VLOOKUP($F20,$F$44:$X$63,5,FALSE) -> 1.1666667 | K20: =VLOOKUP($F20,$F$44:$X$63,6,FALSE) -> 1.5542105 | L20: =VLOOKUP($F20,$F$44:$X$63,7,FALSE) -> 1.1410526 | M20: =VLOOKUP($F20,$F$44:$X$63,8,FALSE) -> 0.88055556 | N20: =VLOOKUP($F20,$F$44:$X$63,9,FALSE) -> 1.8027778 | O20: =G20/$B$13 -> 0.8373364 | P20: =H20/$B$15 -> 0.6599869 | Q20: =I20/$B$17 -> 0.65201391 | R20: =J20/$B$19 -> 0.7739334 | S20: =K20/$B$23 -> 0.97434126 | T20: =L20/$B$25 -> 0.83391437 | U20: =M20/$B$27 -> 0.64471687 | V20: =N20/$B$29 -> 1.1305837
F21: Leicester City | G21: =VLOOKUP($F21,$F$44:$X$63,2,FALSE) * $I$5 + VLOOKUP($F21,$F$75:$X$94,2,FALSE)*$I$4 -> 1.9439726 | H21: =VLOOKUP($F21,$F$44:$X$63,3,FALSE) * $I$5 + VLOOKUP($F21,$F$75:$X$94,3,FALSE)*$I$4 -> 0.8334852 | I21: =VLOOKUP($F21,$F$44:$X$63,4,FALSE) * $I$5 + VLOOKUP($F21,$F$75:$X$94,4,FALSE)*$I$4 -> 1.6840283 | J21: =VLOOKUP($F21,$F$44:$X$63,5,FALSE) * $I$5 + VLOOKUP($F21,$F$75:$X$94,5,FALSE)*$I$4 -> 1.2633037 | K21: =VLOOKUP($F21,$F$44:$X$63,6,FALSE) * $I$5 + VLOOKUP($F21,$F$75:$X$94,6,FALSE)*$I$4 -> 1.5971312 | L21: =VLOOKUP($F21,$F$44:$X$63,7,FALSE) * $I$5 + VLOOKUP($F21,$F$75:$X$94,7,FALSE)*$I$4 -> 1.2837743 | M21: =VLOOKUP($F21,$F$44:$X$63,8,FALSE) * $I$5 + VLOOKUP($F21,$F$75:$X$94,8,FALSE)*$I$4 -> 1.8281218 | N21: =VLOOKUP($F21,$F$44:$X$63,9,FALSE) * $I$5 + VLOOKUP($F21,$F$75:$X$94,9,FALSE)*$I$4 -> 1.369462 | O21: =G21/$B$13 -> 1.2886426 | P21: =H21/$B$15 -> 0.6967798 | Q21: =I21/$B$17 -> 1.411727 | R21: =J21/$B$19 -> 0.83803965 | S21: =K21/$B$23 -> 1.0012484 | T21: =L21/$B$25 -> 0.93821951 | U21: =M21/$B$27 -> 1.338497 | V21: =N21/$B$29 -> 0.85883652
B22: XHome Average goal scored | F22: Liverpool | G22: =VLOOKUP($F22,$F$44:$X$63,2,FALSE) * $I$5 + VLOOKUP($F22,$F$75:$X$94,2,FALSE)*$I$4 -> 2.7369515 | H22: =VLOOKUP($F22,$F$44:$X$63,3,FALSE) * $I$5 + VLOOKUP($F22,$F$75:$X$94,3,FALSE)*$I$4 -> 0.84188657 | I22: =VLOOKUP($F22,$F$44:$X$63,4,FALSE) * $I$5 + VLOOKUP($F22,$F$75:$X$94,4,FALSE)*$I$4 -> 1.6667517 | J22: =VLOOKUP($F22,$F$44:$X$63,5,FALSE) * $I$5 + VLOOKUP($F22,$F$75:$X$94,5,FALSE)*$I$4 -> 0.8887107 | K22: =VLOOKUP($F22,$F$44:$X$63,6,FALSE) * $I$5 + VLOOKUP($F22,$F$75:$X$94,6,FALSE)*$I$4 -> 2.5426097 | L22: =VLOOKUP($F22,$F$44:$X$63,7,FALSE) * $I$5 + VLOOKUP($F22,$F$75:$X$94,7,FALSE)*$I$4 -> 0.98249818 | M22: =VLOOKUP($F22,$F$44:$X$63,8,FALSE) * $I$5 + VLOOKUP($F22,$F$75:$X$94,8,FALSE)*$I$4 -> 1.9921831 | N22: =VLOOKUP($F22,$F$44:$X$63,9,FALSE) * $I$5 + VLOOKUP($F22,$F$75:$X$94,9,FALSE)*$I$4 -> 1.2708676 | O22: =G22/$B$13 -> 1.8143014 | P22: =H22/$B$15 -> 0.7038032 | Q22: =I22/$B$17 -> 1.397244 | R22: =J22/$B$19 -> 0.58954534 | S22: =K22/$B$23 -> 1.593973 | T22: =L22/$B$25 -> 0.71803818 | U22: =M22/$B$27 -> 1.4586179 | V22: =N22/$B$29 -> 0.79700458
B23: =SUM(K11:K30)/20 -> 1.5951398 | F23: Manchester City | G23: =VLOOKUP($F23,$F$44:$X$63,2,FALSE) * $I$5 + VLOOKUP($F23,$F$75:$X$94,2,FALSE)*$I$4 -> 2.8889658 | H23: =VLOOKUP($F23,$F$44:$X$63,3,FALSE) * $I$5 + VLOOKUP($F23,$F$75:$X$94,3,FALSE)*$I$4 -> 0.72215945 | I23: =VLOOKUP($F23,$F$44:$X$63,4,FALSE) * $I$5 + VLOOKUP($F23,$F$75:$X$94,4,FALSE)*$I$4 -> 2.3681659 | J23: =VLOOKUP($F23,$F$44:$X$63,5,FALSE) * $I$5 + VLOOKUP($F23,$F$75:$X$94,5,FALSE)*$I$4 -> 1.1574938 | K23: =VLOOKUP($F23,$F$44:$X$63,6,FALSE) * $I$5 + VLOOKUP($F23,$F$75:$X$94,6,FALSE)*$I$4 -> 2.7584169 | L23: =VLOOKUP($F23,$F$44:$X$63,7,FALSE) * $I$5 + VLOOKUP($F23,$F$75:$X$94,7,FALSE)*$I$4 -> 0.83830569 | M23: =VLOOKUP($F23,$F$44:$X$63,8,FALSE) * $I$5 + VLOOKUP($F23,$F$75:$X$94,8,FALSE)*$I$4 -> 2.7884546 | N23: =VLOOKUP($F23,$F$44:$X$63,9,FALSE) * $I$5 + VLOOKUP($F23,$F$75:$X$94,9,FALSE)*$I$4 -> 1.1948943 | O23: =G23/$B$13 -> 1.9150704 | P23: =H23/$B$15 -> 0.60371332 | Q23: =I23/$B$17 -> 1.985242 | R23: =J23/$B$19 -> 0.76784839 | S23: =K23/$B$23 -> 1.7292634 | T23: =L23/$B$25 -> 0.61265812 | U23: =M23/$B$27 -> 2.0416244 | V23: =N23/$B$29 -> 0.74935913
B24: XHome average goal conceded | F24: Manchester United | G24: =VLOOKUP($F24,$F$44:$X$63,2,FALSE) * $I$5 + VLOOKUP($F24,$F$75:$X$94,2,FALSE)*$I$4 -> 2.105008 | H24: =VLOOKUP($F24,$F$44:$X$63,3,FALSE) * $I$5 + VLOOKUP($F24,$F$75:$X$94,3,FALSE)*$I$4 -> 0.89502843 | I24: =VLOOKUP($F24,$F$44:$X$63,4,FALSE) * $I$5 + VLOOKUP($F24,$F$75:$X$94,4,FALSE)*$I$4 -> 1.3335763 | J24: =VLOOKUP($F24,$F$44:$X$63,5,FALSE) * $I$5 + VLOOKUP($F24,$F$75:$X$94,5,FALSE)*$I$4 -> 1.0558816 | K24: =VLOOKUP($F24,$F$44:$X$63,6,FALSE) * $I$5 + VLOOKUP($F24,$F$75:$X$94,6,FALSE)*$I$4 -> 1.8290286 | L24: =VLOOKUP($F24,$F$44:$X$63,7,FALSE) * $I$5 + VLOOKUP($F24,$F$75:$X$94,7,FALSE)*$I$4 -> 0.97126075 | M24: =VLOOKUP($F24,$F$44:$X$63,8,FALSE) * $I$5 + VLOOKUP($F24,$F$75:$X$94,8,FALSE)*$I$4 -> 1.5717144 | N24: =VLOOKUP($F24,$F$44:$X$63,9,FALSE) * $I$5 + VLOOKUP($F24,$F$75:$X$94,9,FALSE)*$I$4 -> 1.1841953 | O24: =G24/$B$13 -> 1.3953915 | P24: =H24/$B$15 -> 0.74822891 | Q24: =I24/$B$17 -> 1.1179418 | R24: =J24/$B$19 -> 0.70044173 | S24: =K24/$B$23 -> 1.1466259 | T24: =L24/$B$25 -> 0.70982554 | U24: =M24/$B$27 -> 1.150763 | V24: =N24/$B$29 -> 0.74264941
B25: =SUM(L11:L30)/20 -> 1.3683091 | F25: Newcastle | G25: =VLOOKUP($F25,$F$44:$X$63,2,FALSE) * $I$5 + VLOOKUP($F25,$F$75:$X$94,2,FALSE)*$I$4 -> 1.0556993 | H25: =VLOOKUP($F25,$F$44:$X$63,3,FALSE) * $I$5 + VLOOKUP($F25,$F$75:$X$94,3,FALSE)*$I$4 -> 1.0002187 | I25: =VLOOKUP($F25,$F$44:$X$63,4,FALSE) * $I$5 + VLOOKUP($F25,$F$75:$X$94,4,FALSE)*$I$4 -> 0.94736842 | J25: =VLOOKUP($F25,$F$44:$X$63,5,FALSE) * $I$5 + VLOOKUP($F25,$F$75:$X$94,5,FALSE)*$I$4 -> 1.9468581 | K25: =VLOOKUP($F25,$F$44:$X$63,6,FALSE) * $I$5 + VLOOKUP($F25,$F$75:$X$94,6,FALSE)*$I$4 -> 1.0684686 | L25: =VLOOKUP($F25,$F$44:$X$63,7,FALSE) * $I$5 + VLOOKUP($F25,$F$75:$X$94,7,FALSE)*$I$4 -> 1.7325557 | M25: =VLOOKUP($F25,$F$44:$X$63,8,FALSE) * $I$5 + VLOOKUP($F25,$F$75:$X$94,8,FALSE)*$I$4 -> 0.95156947 | N25: =VLOOKUP($F25,$F$44:$X$63,9,FALSE) * $I$5 + VLOOKUP($F25,$F$75:$X$94,9,FALSE)*$I$4 -> 1.9440574 | O25: =G25/$B$13 -> 0.69981392 | P25: =H25/$B$15 -> 0.83616623 | Q25: =I25/$B$17 -> 0.79418235 | R25: =J25/$B$19 -> 1.2914902 | S25: =K25/$B$23 -> 0.66982757 | T25: =L25/$B$25 -> 1.266202 | U25: =M25/$B$27 -> 0.69671117 | V25: =N25/$B$29 -> 1.219185
B26: XAway Average goal scored | F26: Southampton | G26: =VLOOKUP($F26,$F$44:$X$63,2,FALSE) * $I$5 + VLOOKUP($F26,$F$75:$X$94,2,FALSE)*$I$4 -> 1.0002916 | H26: =VLOOKUP($F26,$F$44:$X$63,3,FALSE) * $I$5 + VLOOKUP($F26,$F$75:$X$94,3,FALSE)*$I$4 -> 1.8886742 | I26: =VLOOKUP($F26,$F$44:$X$63,4,FALSE) * $I$5 + VLOOKUP($F26,$F$75:$X$94,4,FALSE)*$I$4 -> 1.57851 | J26: =VLOOKUP($F26,$F$44:$X$63,5,FALSE) * $I$5 + VLOOKUP($F26,$F$75:$X$94,5,FALSE)*$I$4 -> 1.316154 | K26: =VLOOKUP($F26,$F$44:$X$63,6,FALSE) * $I$5 + VLOOKUP($F26,$F$75:$X$94,6,FALSE)*$I$4 -> 1.2834331 | L26: =VLOOKUP($F26,$F$44:$X$63,7,FALSE) * $I$5 + VLOOKUP($F26,$F$75:$X$94,7,FALSE)*$I$4 -> 1.7392451 | M26: =VLOOKUP($F26,$F$44:$X$63,8,FALSE) * $I$5 + VLOOKUP($F26,$F$75:$X$94,8,FALSE)*$I$4 -> 1.6034546 | N26: =VLOOKUP($F26,$F$44:$X$63,9,FALSE) * $I$5 + VLOOKUP($F26,$F$75:$X$94,9,FALSE)*$I$4 -> 1.4659385 | O26: =G26/$B$13 -> 0.66308461 | P26: =H26/$B$15 -> 1.5789003 | Q26: =I26/$B$17 -> 1.3232706 | R26: =J26/$B$19 -> 0.87309901 | S26: =K26/$B$23 -> 0.80458971 | T26: =L26/$B$25 -> 1.2710908 | U26: =M26/$B$27 -> 1.1740023 | V26: =N26/$B$29 -> 0.91934026
B27: =SUM(M11:M30)/20 -> 1.365802 | F27: Tottenham Hotspur | G27: =VLOOKUP($F27,$F$44:$X$63,2,FALSE) * $I$5 + VLOOKUP($F27,$F$75:$X$94,2,FALSE)*$I$4 -> 1.8946639 | H27: =VLOOKUP($F27,$F$44:$X$63,3,FALSE) * $I$5 + VLOOKUP($F27,$F$75:$X$94,3,FALSE)*$I$4 -> 0.89470039 | I27: =VLOOKUP($F27,$F$44:$X$63,4,FALSE) * $I$5 + VLOOKUP($F27,$F$75:$X$94,4,FALSE)*$I$4 -> 1.3336128 | J27: =VLOOKUP($F27,$F$44:$X$63,5,FALSE) * $I$5 + VLOOKUP($F27,$F$75:$X$94,5,FALSE)*$I$4 -> 1.6108337 | K27: =VLOOKUP($F27,$F$44:$X$63,6,FALSE) * $I$5 + VLOOKUP($F27,$F$75:$X$94,6,FALSE)*$I$4 -> 1.6591034 | L27: =VLOOKUP($F27,$F$44:$X$63,7,FALSE) * $I$5 + VLOOKUP($F27,$F$75:$X$94,7,FALSE)*$I$4 -> 1.3016675 | M27: =VLOOKUP($F27,$F$44:$X$63,8,FALSE) * $I$5 + VLOOKUP($F27,$F$75:$X$94,8,FALSE)*$I$4 -> 1.362349 | N27: =VLOOKUP($F27,$F$44:$X$63,9,FALSE) * $I$5 + VLOOKUP($F27,$F$75:$X$94,9,FALSE)*$I$4 -> 1.7224314 | O27: =G27/$B$13 -> 1.2559563 | P27: =H27/$B$15 -> 0.74795468 | Q27: =I27/$B$17 -> 1.1179724 | R27: =J27/$B$19 -> 1.0685811 | S27: =K27/$B$23 -> 1.040099 | T27: =L27/$B$25 -> 0.95129639 | U27: =M27/$B$27 -> 0.99747184 | V27: =N27/$B$29 -> 1.0801957
B28: XAway average goal conceded | F28: Watford | G28: =VLOOKUP($F28,$F$44:$X$63,2,FALSE) * $I$5 + VLOOKUP($F28,$F$75:$X$94,2,FALSE)*$I$4 -> 1.1580405 | H28: =VLOOKUP($F28,$F$44:$X$63,3,FALSE) * $I$5 + VLOOKUP($F28,$F$75:$X$94,3,FALSE)*$I$4 -> 1.4210891 | I28: =VLOOKUP($F28,$F$44:$X$63,4,FALSE) * $I$5 + VLOOKUP($F28,$F$75:$X$94,4,FALSE)*$I$4 -> 0.66715265 | J28: =VLOOKUP($F28,$F$44:$X$63,5,FALSE) * $I$5 + VLOOKUP($F28,$F$75:$X$94,5,FALSE)*$I$4 -> 1.8887107 | K28: =VLOOKUP($F28,$F$44:$X$63,6,FALSE) * $I$5 + VLOOKUP($F28,$F$75:$X$94,6,FALSE)*$I$4 -> 1.5814036 | L28: =VLOOKUP($F28,$F$44:$X$63,7,FALSE) * $I$5 + VLOOKUP($F28,$F$75:$X$94,7,FALSE)*$I$4 -> 1.5195513 | M28: =VLOOKUP($F28,$F$44:$X$63,8,FALSE) * $I$5 + VLOOKUP($F28,$F$75:$X$94,8,FALSE)*$I$4 -> 0.92086608 | N28: =VLOOKUP($F28,$F$44:$X$63,9,FALSE) * $I$5 + VLOOKUP($F28,$F$75:$X$94,9,FALSE)*$I$4 -> 1.6523399 | O28: =G28/$B$13 -> 0.76765501 | P28: =H28/$B$15 -> 1.1880069 | Q28: =I28/$B$17 -> 0.55927646 | R28: =J28/$B$19 -> 1.2529168 | S28: =K28/$B$23 -> 0.99138873 | T28: =L28/$B$25 -> 1.1105322 | U28: =M28/$B$27 -> 0.67423104 | V28: =N28/$B$29 -> 1.0362389
B29: =SUM(N11:N30)/20 -> 1.5945549 | F29: West Ham United | G29: =VLOOKUP($F29,$F$44:$X$63,2,FALSE) * $I$5 + VLOOKUP($F29,$F$75:$X$94,2,FALSE)*$I$4 -> 1.6111617 | H29: =VLOOKUP($F29,$F$44:$X$63,3,FALSE) * $I$5 + VLOOKUP($F29,$F$75:$X$94,3,FALSE)*$I$4 -> 1.7775307 | I29: =VLOOKUP($F29,$F$44:$X$63,4,FALSE) * $I$5 + VLOOKUP($F29,$F$75:$X$94,4,FALSE)*$I$4 -> 1.0000364 | J29: =VLOOKUP($F29,$F$44:$X$63,5,FALSE) * $I$5 + VLOOKUP($F29,$F$75:$X$94,5,FALSE)*$I$4 -> 1.5262793 | K29: =VLOOKUP($F29,$F$44:$X$63,6,FALSE) * $I$5 + VLOOKUP($F29,$F$75:$X$94,6,FALSE)*$I$4 -> 1.4360733 | L29: =VLOOKUP($F29,$F$44:$X$63,7,FALSE) * $I$5 + VLOOKUP($F29,$F$75:$X$94,7,FALSE)*$I$4 -> 1.701987 | M29: =VLOOKUP($F29,$F$44:$X$63,8,FALSE) * $I$5 + VLOOKUP($F29,$F$75:$X$94,8,FALSE)*$I$4 -> 1.2468232 | N29: =VLOOKUP($F29,$F$44:$X$63,9,FALSE) * $I$5 + VLOOKUP($F29,$F$75:$X$94,9,FALSE)*$I$4 -> 2.0053627 | O29: =G29/$B$13 -> 1.0680251 | P29: =H29/$B$15 -> 1.4859862 | Q29: =I29/$B$17 -> 0.83833415 | R29: =J29/$B$19 -> 1.0124902 | S29: =K29/$B$23 -> 0.90028055 | T29: =L29/$B$25 -> 1.2438615 | U29: =M29/$B$27 -> 0.91288722 | V29: =N29/$B$29 -> 1.2576316
F30: Wolverhampton | G30: =VLOOKUP($F30,$F$44:$X$63,2,FALSE) * $I$5 + VLOOKUP($F30,$F$75:$X$94,2,FALSE)*$I$4 -> 1.4210891 | H30: =VLOOKUP($F30,$F$44:$X$63,3,FALSE) * $I$5 + VLOOKUP($F30,$F$75:$X$94,3,FALSE)*$I$4 -> 1.0000729 | I30: =VLOOKUP($F30,$F$44:$X$63,4,FALSE) * $I$5 + VLOOKUP($F30,$F$75:$X$94,4,FALSE)*$I$4 -> 1.3331025 | J30: =VLOOKUP($F30,$F$44:$X$63,5,FALSE) * $I$5 + VLOOKUP($F30,$F$75:$X$94,5,FALSE)*$I$4 -> 1.0557358 | K30: =VLOOKUP($F30,$F$44:$X$63,6,FALSE) * $I$5 + VLOOKUP($F30,$F$75:$X$94,6,FALSE)*$I$4 -> 1.4806962 | L30: =VLOOKUP($F30,$F$44:$X$63,7,FALSE) * $I$5 + VLOOKUP($F30,$F$75:$X$94,7,FALSE)*$I$4 -> 0.97692885 | M30: =VLOOKUP($F30,$F$44:$X$63,8,FALSE) * $I$5 + VLOOKUP($F30,$F$75:$X$94,8,FALSE)*$I$4 -> 1.4253749 | N30: =VLOOKUP($F30,$F$44:$X$63,9,FALSE) * $I$5 + VLOOKUP($F30,$F$75:$X$94,9,FALSE)*$I$4 -> 1.0862454 | O30: =G30/$B$13 -> 0.94202761 | P30: =H30/$B$15 -> 0.83604434 | Q30: =I30/$B$17 -> 1.1175446 | R30: =J30/$B$19 -> 0.70034501 | S30: =K30/$B$23 -> 0.92825479 | T30: =L30/$B$25 -> 0.71396795 | U30: =M30/$B$27 -> 1.0436176 | V30: =N30/$B$29 -> 0.68122167
G41: Season 19/20 | H41: Number of Games | I41: =SUM(W44:X63) -> 740
G43: HGS | H43: HGC | I43: AGS | J43: AGC | K43: HXGS | L43: HXGC | M43: AXGS | N43: AXGC | O43: Home AS | P43: Home DW | Q43: Away AS | R43: Away DW | S43: XHome AS | T43: XHome DW | U43: XAway AS | V43: XAway DW | W43: HGP | X43: AGP
F44: AFC Bournemouth | G44: =SUMIF('EPL DATA'!$F$1143:$F$1512,$F44,'EPL DATA'!$Q$1143:$Q$1512)/$W44 -> 1.1578947 | H44: =SUMIF('EPL DATA'!$F$1143:$F$1512,$F44,'EPL DATA'!$R$1143:$R$1512)/$W44 -> 1.5789474 | I44: =SUMIF('EPL DATA'!$G$1143:$G$1512,$F44,'EPL DATA'!$R$1143:$R$1512)/$X44 -> 0.83333333 | J44: =SUMIF('EPL DATA'!$G$1143:$G$1512,$F44,'EPL DATA'!$Q$1143:$Q$1512)/$X44 -> 1.8888889 | K44: =SUMIF('EPL DATA'!$F$1143:$F$1512,$F44,'EPL DATA'!$S$1143:$S$1512)/$W44 -> 1.3094737 | L44: =SUMIF('EPL DATA'!$F$1143:$F$1512,$F44,'EPL DATA'!$T$1143:$T$1512)/$W44 -> 1.6331579 | M44: =SUMIF('EPL DATA'!$G$1143:$G$1512,$F44,'EPL DATA'!$T$1143:$T$1512)/$X44 -> 1.1344444 | N44: =SUMIF('EPL DATA'!$G$1143:$G$1512,$F44,'EPL DATA'!$S$1143:$S$1512)/$X44 -> 1.7755556 | O44: =G44/$B$46 -> 0.76759062 | P44: =H44/$B$48 -> 1.3199707 | Q44: =I44/$B$50 -> 0.69861503 | R44: =J44/$B$52 -> 1.2530307 | S44: =K44/$B$56 -> 0.8209302 | T44: =L44/$B$58 -> 1.1935266 | U44: =M44/$B$60 -> 0.83059042 | V44: =N44/$B$62 -> 1.1135123 | W44: =COUNTIF('EPL DATA'!$F$1143:$F$1512, $F44) -> 19 | X44: =COUNTIF('EPL DATA'!$G$1143:$G$1512, $F44) -> 18
B45: Home Average goal scored | F45: Arsenal | G45: =SUMIF('EPL DATA'!$F$1143:$F$1512,$F45,'EPL DATA'!$Q$1143:$Q$1512)/$W45 -> 1.8333333 | H45: =SUMIF('EPL DATA'!$F$1143:$F$1512,$F45,'EPL DATA'!$R$1143:$R$1512)/$W45 -> 1.2222222 | I45: =SUMIF('EPL DATA'!$G$1143:$G$1512,$F45,'EPL DATA'!$R$1143:$R$1512)/$X45 -> 1.0526316 | J45: =SUMIF('EPL DATA'!$G$1143:$G$1512,$F45,'EPL DATA'!$Q$1143:$Q$1512)/$X45 -> 1.2631579 | K45: =SUMIF('EPL DATA'!$F$1143:$F$1512,$F45,'EPL DATA'!$S$1143:$S$1512)/$W45 -> 1.4822222 | L45: =SUMIF('EPL DATA'!$F$1143:$F$1512,$F45,'EPL DATA'!$T$1143:$T$1512)/$W45 -> 1.5822222 | M45: =SUMIF('EPL DATA'!$G$1143:$G$1512,$F45,'EPL DATA'!$T$1143:$T$1512)/$X45 -> 1.2573684 | N45: =SUMIF('EPL DATA'!$G$1143:$G$1512,$F45,'EPL DATA'!$S$1143:$S$1512)/$X45 -> 1.4652632 | O45: =G45/$B$46 -> 1.2153518 | P45: =H45/$B$48 -> 1.0217551 | Q45: =I45/$B$50 -> 0.88246109 | R45: =J45/$B$52 -> 0.83794006 | S45: =K45/$B$56 -> 0.92922905 | T45: =L45/$B$58 -> 1.1563023 | U45: =M45/$B$60 -> 0.92058996 | V45: =N45/$B$62 -> 0.91891718 | W45: =COUNTIF('EPL DATA'!$F$1143:$F$1512, $F45) -> 18 | X45: =COUNTIF('EPL DATA'!$G$1143:$G$1512, $F45) -> 19
B46: =SUM(G44:G63)/20 -> 1.5084795 | F46: Brighton and Hove Albion | G46: =SUMIF('EPL DATA'!$F$1143:$F$1512,$F46,'EPL DATA'!$Q$1143:$Q$1512)/$W46 -> 1.0526316 | H46: =SUMIF('EPL DATA'!$F$1143:$F$1512,$F46,'EPL DATA'!$R$1143:$R$1512)/$W46 -> 1.4210526 | I46: =SUMIF('EPL DATA'!$G$1143:$G$1512,$F46,'EPL DATA'!$R$1143:$R$1512)/$X46 -> 0.94444444 | J46: =SUMIF('EPL DATA'!$G$1143:$G$1512,$F46,'EPL DATA'!$Q$1143:$Q$1512)/$X46 -> 1.4444444 | K46: =SUMIF('EPL DATA'!$F$1143:$F$1512,$F46,'EPL DATA'!$S$1143:$S$1512)/$W46 -> 1.3252632 | L46: =SUMIF('EPL DATA'!$F$1143:$F$1512,$F46,'EPL DATA'!$T$1143:$T$1512)/$W46 -> 1.4736842 | M46: =SUMIF('EPL DATA'!$G$1143:$G$1512,$F46,'EPL DATA'!$T$1143:$T$1512)/$X46 -> 1.2566667 | N46: =SUMIF('EPL DATA'!$G$1143:$G$1512,$F46,'EPL DATA'!$S$1143:$S$1512)/$X46 -> 1.6744444 | O46: =G46/$B$46 -> 0.69780965 | P46: =H46/$B$48 -> 1.1879736 | Q46: =I46/$B$50 -> 0.7917637 | R46: =J46/$B$52 -> 0.95819998 | S46: =K46/$B$56 -> 0.83082888 | T46: =L46/$B$58 -> 1.0769818 | U46: =M46/$B$60 -> 0.92007617 | V46: =N46/$B$62 -> 1.050102 | W46: =COUNTIF('EPL DATA'!$F$1143:$F$1512, $F46) -> 19 | X46: =COUNTIF('EPL DATA'!$G$1143:$G$1512, $F46) -> 18
B47: Home average goal conceded | F47: Burnley | G47: =SUMIF('EPL DATA'!$F$1143:$F$1512,$F47,'EPL DATA'!$Q$1143:$Q$1512)/$W47 -> 1.2777778 | H47: =SUMIF('EPL DATA'!$F$1143:$F$1512,$F47,'EPL DATA'!$R$1143:$R$1512)/$W47 -> 1.1666667 | I47: =SUMIF('EPL DATA'!$G$1143:$G$1512,$F47,'EPL DATA'!$R$1143:$R$1512)/$X47 -> 1 | J47: =SUMIF('EPL DATA'!$G$1143:$G$1512,$F47,'EPL DATA'!$Q$1143:$Q$1512)/$X47 -> 1.4210526 | K47: =SUMIF('EPL DATA'!$F$1143:$F$1512,$F47,'EPL DATA'!$S$1143:$S$1512)/$W47 -> 1.6644444 | L47: =SUMIF('EPL DATA'!$F$1143:$F$1512,$F47,'EPL DATA'!$T$1143:$T$1512)/$W47 -> 1.4066667 | M47: =SUMIF('EPL DATA'!$G$1143:$G$1512,$F47,'EPL DATA'!$T$1143:$T$1512)/$X47 -> 1.0278947 | N47: =SUMIF('EPL DATA'!$G$1143:$G$1512,$F47,'EPL DATA'!$S$1143:$S$1512)/$X47 -> 1.5836842 | O47: =G47/$B$46 -> 0.84706338 | P47: =H47/$B$48 -> 0.97531166 | Q47: =I47/$B$50 -> 0.83833803 | R47: =J47/$B$52 -> 0.94268257 | S47: =K47/$B$56 -> 1.0434671 | T47: =L47/$B$58 -> 1.0280047 | U47: =M47/$B$60 -> 0.75257941 | V47: =N47/$B$62 -> 0.99318312 | W47: =COUNTIF('EPL DATA'!$F$1143:$F$1512, $F47) -> 18 | X47: =COUNTIF('EPL DATA'!$G$1143:$G$1512, $F47) -> 19
B48: =SUM(H44:H63)/20 -> 1.1961988 | F48: Aston Villa | G48: =SUMIF('EPL DATA'!$F$1143:$F$1512,$F48,'EPL DATA'!$Q$1143:$Q$1512)/$W48 -> 1.1578947 | H48: =SUMIF('EPL DATA'!$F$1143:$F$1512,$F48,'EPL DATA'!$R$1143:$R$1512)/$W48 -> 1.5789474 | I48: =SUMIF('EPL DATA'!$G$1143:$G$1512,$F48,'EPL DATA'!$R$1143:$R$1512)/$X48 -> 1 | J48: =SUMIF('EPL DATA'!$G$1143:$G$1512,$F48,'EPL DATA'!$Q$1143:$Q$1512)/$X48 -> 2 | K48: =SUMIF('EPL DATA'!$F$1143:$F$1512,$F48,'EPL DATA'!$S$1143:$S$1512)/$W48 -> 1.3542105 | L48: =SUMIF('EPL DATA'!$F$1143:$F$1512,$F48,'EPL DATA'!$T$1143:$T$1512)/$W48 -> 1.8184211 | M48: =SUMIF('EPL DATA'!$G$1143:$G$1512,$F48,'EPL DATA'!$T$1143:$T$1512)/$X48 -> 1.1483333 | N48: =SUMIF('EPL DATA'!$G$1143:$G$1512,$F48,'EPL DATA'!$S$1143:$S$1512)/$X48 -> 2.1072222 | O48: =G48/$B$46 -> 0.76759062 | P48: =H48/$B$48 -> 1.3199707 | Q48: =I48/$B$50 -> 0.83833803 | R48: =J48/$B$52 -> 1.3267384 | S48: =K48/$B$56 -> 0.84897645 | T48: =L48/$B$58 -> 1.3289186 | U48: =M48/$B$60 -> 0.84075926 | V48: =N48/$B$62 -> 1.3215119 | W48: =COUNTIF('EPL DATA'!$F$1143:$F$1512, $F48) -> 19 | X48: =COUNTIF('EPL DATA'!$G$1143:$G$1512, $F48) -> 18
B49: Away Average goal scored | F49: Chelsea | G49: =SUMIF('EPL DATA'!$F$1143:$F$1512,$F49,'EPL DATA'!$Q$1143:$Q$1512)/$W49 -> 1.5555556 | H49: =SUMIF('EPL DATA'!$F$1143:$F$1512,$F49,'EPL DATA'!$R$1143:$R$1512)/$W49 -> 0.88888889 | I49: =SUMIF('EPL DATA'!$G$1143:$G$1512,$F49,'EPL DATA'!$R$1143:$R$1512)/$X49 -> 2.0526316 | J49: =SUMIF('EPL DATA'!$G$1143:$G$1512,$F49,'EPL DATA'!$Q$1143:$Q$1512)/$X49 -> 2 | K49: =SUMIF('EPL DATA'!$F$1143:$F$1512,$F49,'EPL DATA'!$S$1143:$S$1512)/$W49 -> 2.5222222 | L49: =SUMIF('EPL DATA'!$F$1143:$F$1512,$F49,'EPL DATA'!$T$1143:$T$1512)/$W49 -> 0.78277778 | M49: =SUMIF('EPL DATA'!$G$1143:$G$1512,$F49,'EPL DATA'!$T$1143:$T$1512)/$X49 -> 1.7063158 | N49: =SUMIF('EPL DATA'!$G$1143:$G$1512,$F49,'EPL DATA'!$S$1143:$S$1512)/$X49 -> 1.4678947 | O49: =G49/$B$46 -> 1.0312076 | P49: =H49/$B$48 -> 0.7430946 | Q49: =I49/$B$50 -> 1.7207991 | R49: =J49/$B$52 -> 1.3267384 | S49: =K49/$B$56 -> 1.5812218 | T49: =L49/$B$58 -> 0.57206108 | U49: =M49/$B$60 -> 1.2492895 | V49: =N49/$B$62 -> 0.92056754 | W49: =COUNTIF('EPL DATA'!$F$1143:$F$1512, $F49) -> 18 | X49: =COUNTIF('EPL DATA'!$G$1143:$G$1512, $F49) -> 19
B50: =SUM(I44:I63)/20 -> 1.1928363 | F50: Crystal Palace | G50: =SUMIF('EPL DATA'!$F$1143:$F$1512,$F50,'EPL DATA'!$Q$1143:$Q$1512)/$W50 -> 0.77777778 | H50: =SUMIF('EPL DATA'!$F$1143:$F$1512,$F50,'EPL DATA'!$R$1143:$R$1512)/$W50 -> 1.0555556 | I50: =SUMIF('EPL DATA'!$G$1143:$G$1512,$F50,'EPL DATA'!$R$1143:$R$1512)/$X50 -> 0.84210526 | J50: =SUMIF('EPL DATA'!$G$1143:$G$1512,$F50,'EPL DATA'!$Q$1143:$Q$1512)/$X50 -> 1.5789474 | K50: =SUMIF('EPL DATA'!$F$1143:$F$1512,$F50,'EPL DATA'!$S$1143:$S$1512)/$W50 -> 1.055 | L50: =SUMIF('EPL DATA'!$F$1143:$F$1512,$F50,'EPL DATA'!$T$1143:$T$1512)/$W50 -> 1.2966667 | M50: =SUMIF('EPL DATA'!$G$1143:$G$1512,$F50,'EPL DATA'!$T$1143:$T$1512)/$X50 -> 0.91105263 | N50: =SUMIF('EPL DATA'!$G$1143:$G$1512,$F50,'EPL DATA'!$S$1143:$S$1512)/$X50 -> 1.9394737 | O50: =G50/$B$46 -> 0.5156038 | P50: =H50/$B$48 -> 0.88242484 | Q50: =I50/$B$50 -> 0.70596887 | R50: =J50/$B$52 -> 1.0474251 | S50: =K50/$B$56 -> 0.66139654 | T50: =L50/$B$58 -> 0.94761574 | U50: =M50/$B$60 -> 0.66703274 | V50: =N50/$B$62 -> 1.216311 | W50: =COUNTIF('EPL DATA'!$F$1143:$F$1512, $F50) -> 18 | X50: =COUNTIF('EPL DATA'!$G$1143:$G$1512, $F50) -> 19
B51: Away average goal conceded | F51: Everton | G51: =SUMIF('EPL DATA'!$F$1143:$F$1512,$F51,'EPL DATA'!$Q$1143:$Q$1512)/$W51 -> 1.2777778 | H51: =SUMIF('EPL DATA'!$F$1143:$F$1512,$F51,'EPL DATA'!$R$1143:$R$1512)/$W51 -> 1 | I51: =SUMIF('EPL DATA'!$G$1143:$G$1512,$F51,'EPL DATA'!$R$1143:$R$1512)/$X51 -> 1.0526316 | J51: =SUMIF('EPL DATA'!$G$1143:$G$1512,$F51,'EPL DATA'!$Q$1143:$Q$1512)/$X51 -> 1.8421053 | K51: =SUMIF('EPL DATA'!$F$1143:$F$1512,$F51,'EPL DATA'!$S$1143:$S$1512)/$W51 -> 1.4344444 | L51: =SUMIF('EPL DATA'!$F$1143:$F$1512,$F51,'EPL DATA'!$T$1143:$T$1512)/$W51 -> 1.2466667 | M51: =SUMIF('EPL DATA'!$G$1143:$G$1512,$F51,'EPL DATA'!$T$1143:$T$1512)/$X51 -> 1.3394737 | N51: =SUMIF('EPL DATA'!$G$1143:$G$1512,$F51,'EPL DATA'!$S$1143:$S$1512)/$X51 -> 1.3642105 | O51: =G51/$B$46 -> 0.84706338 | P51: =H51/$B$48 -> 0.83598142 | Q51: =I51/$B$50 -> 0.88246109 | R51: =J51/$B$52 -> 1.2219959 | S51: =K51/$B$56 -> 0.89927639 | T51: =L51/$B$58 -> 0.91107528 | U51: =M51/$B$60 -> 0.98070383 | V51: =N51/$B$62 -> 0.85554359 | W51: =COUNTIF('EPL DATA'!$F$1143:$F$1512, $F51) -> 18 | X51: =COUNTIF('EPL DATA'!$G$1143:$G$1512, $F51) -> 19
B52: =SUM(J44:J63)/20 -> 1.5074561 | F52: Norwich City | G52: =SUMIF('EPL DATA'!$F$1143:$F$1512,$F52,'EPL DATA'!$Q$1143:$Q$1512)/$W52 -> 1 | H52: =SUMIF('EPL DATA'!$F$1143:$F$1512,$F52,'EPL DATA'!$R$1143:$R$1512)/$W52 -> 1.9473684 | I52: =SUMIF('EPL DATA'!$G$1143:$G$1512,$F52,'EPL DATA'!$R$1143:$R$1512)/$X52 -> 0.38888889 | J52: =SUMIF('EPL DATA'!$G$1143:$G$1512,$F52,'EPL DATA'!$Q$1143:$Q$1512)/$X52 -> 1.8333333 | K52: =SUMIF('EPL DATA'!$F$1143:$F$1512,$F52,'EPL DATA'!$S$1143:$S$1512)/$W52 -> 0.96473684 | L52: =SUMIF('EPL DATA'!$F$1143:$F$1512,$F52,'EPL DATA'!$T$1143:$T$1512)/$W52 -> 1.9373684 | M52: =SUMIF('EPL DATA'!$G$1143:$G$1512,$F52,'EPL DATA'!$T$1143:$T$1512)/$X52 -> 0.96277778 | N52: =SUMIF('EPL DATA'!$G$1143:$G$1512,$F52,'EPL DATA'!$S$1143:$S$1512)/$X52 -> 1.8144444 | O52: =G52/$B$46 -> 0.66291917 | P52: =H52/$B$48 -> 1.6279638 | Q52: =I52/$B$50 -> 0.32602035 | R52: =J52/$B$52 -> 1.2161769 | S52: =K52/$B$56 -> 0.60480911 | T52: =L52/$B$58 -> 1.4158464 | U52: =M52/$B$60 -> 0.70490363 | V52: =N52/$B$62 -> 1.1379008 | W52: =COUNTIF('EPL DATA'!$F$1143:$F$1512, $F52) -> 19 | X52: =COUNTIF('EPL DATA'!$G$1143:$G$1512, $F52) -> 18
F53: Sheffield United | G53: =SUMIF('EPL DATA'!$F$1143:$F$1512,$F53,'EPL DATA'!$Q$1143:$Q$1512)/$W53 -> 1.2631579 | H53: =SUMIF('EPL DATA'!$F$1143:$F$1512,$F53,'EPL DATA'!$R$1143:$R$1512)/$W53 -> 0.78947368 | I53: =SUMIF('EPL DATA'!$G$1143:$G$1512,$F53,'EPL DATA'!$R$1143:$R$1512)/$X53 -> 0.77777778 | J53: =SUMIF('EPL DATA'!$G$1143:$G$1512,$F53,'EPL DATA'!$Q$1143:$Q$1512)/$X53 -> 1.1666667 | K53: =SUMIF('EPL DATA'!$F$1143:$F$1512,$F53,'EPL DATA'!$S$1143:$S$1512)/$W53 -> 1.5542105 | L53: =SUMIF('EPL DATA'!$F$1143:$F$1512,$F53,'EPL DATA'!$T$1143:$T$1512)/$W53 -> 1.1410526 | M53: =SUMIF('EPL DATA'!$G$1143:$G$1512,$F53,'EPL DATA'!$T$1143:$T$1512)/$X53 -> 0.88055556 | N53: =SUMIF('EPL DATA'!$G$1143:$G$1512,$F53,'EPL DATA'!$S$1143:$S$1512)/$X53 -> 1.8027778 | O53: =G53/$B$46 -> 0.83737158 | P53: =H53/$B$48 -> 0.65998533 | Q53: =I53/$B$50 -> 0.65204069 | R53: =J53/$B$52 -> 0.77393075 | S53: =K53/$B$56 -> 0.97435968 | T53: =L53/$B$58 -> 0.83389159 | U53: =M53/$B$60 -> 0.64470412 | V53: =N53/$B$62 -> 1.1305843 | W53: =COUNTIF('EPL DATA'!$F$1143:$F$1512, $F53) -> 19 | X53: =COUNTIF('EPL DATA'!$G$1143:$G$1512, $F53) -> 18
F54: Leicester City | G54: =SUMIF('EPL DATA'!$F$1143:$F$1512,$F54,'EPL DATA'!$Q$1143:$Q$1512)/$W54 -> 1.9444444 | H54: =SUMIF('EPL DATA'!$F$1143:$F$1512,$F54,'EPL DATA'!$R$1143:$R$1512)/$W54 -> 0.83333333 | I54: =SUMIF('EPL DATA'!$G$1143:$G$1512,$F54,'EPL DATA'!$R$1143:$R$1512)/$X54 -> 1.6842105 | J54: =SUMIF('EPL DATA'!$G$1143:$G$1512,$F54,'EPL DATA'!$Q$1143:$Q$1512)/$X54 -> 1.2631579 | K54: =SUMIF('EPL DATA'!$F$1143:$F$1512,$F54,'EPL DATA'!$S$1143:$S$1512)/$W54 -> 1.5972222 | L54: =SUMIF('EPL DATA'!$F$1143:$F$1512,$F54,'EPL DATA'!$T$1143:$T$1512)/$W54 -> 1.2838889 | M54: =SUMIF('EPL DATA'!$G$1143:$G$1512,$F54,'EPL DATA'!$T$1143:$T$1512)/$X54 -> 1.8284211 | N54: =SUMIF('EPL DATA'!$G$1143:$G$1512,$F54,'EPL DATA'!$S$1143:$S$1512)/$X54 -> 1.3694737 | O54: =G54/$B$46 -> 1.2890095 | P54: =H54/$B$48 -> 0.69665119 | Q54: =I54/$B$50 -> 1.4119377 | R54: =J54/$B$52 -> 0.83794006 | S54: =K54/$B$56 -> 1.0013244 | T54: =L54/$B$58 -> 0.93827762 | U54: =M54/$B$60 -> 1.3386896 | V54: =N54/$B$62 -> 0.85884429 | W54: =COUNTIF('EPL DATA'!$F$1143:$F$1512, $F54) -> 18 | X54: =COUNTIF('EPL DATA'!$G$1143:$G$1512, $F54) -> 19
B55: XHome Average goal scored | F55: Liverpool | G55: =SUMIF('EPL DATA'!$F$1143:$F$1512,$F55,'EPL DATA'!$Q$1143:$Q$1512)/$W55 -> 2.7368421 | H55: =SUMIF('EPL DATA'!$F$1143:$F$1512,$F55,'EPL DATA'!$R$1143:$R$1512)/$W55 -> 0.84210526 | I55: =SUMIF('EPL DATA'!$G$1143:$G$1512,$F55,'EPL DATA'!$R$1143:$R$1512)/$X55 -> 1.6666667 | J55: =SUMIF('EPL DATA'!$G$1143:$G$1512,$F55,'EPL DATA'!$Q$1143:$Q$1512)/$X55 -> 0.88888889 | K55: =SUMIF('EPL DATA'!$F$1143:$F$1512,$F55,'EPL DATA'!$S$1143:$S$1512)/$W55 -> 2.5426316 | L55: =SUMIF('EPL DATA'!$F$1143:$F$1512,$F55,'EPL DATA'!$T$1143:$T$1512)/$W55 -> 0.98263158 | M55: =SUMIF('EPL DATA'!$G$1143:$G$1512,$F55,'EPL DATA'!$T$1143:$T$1512)/$X55 -> 1.9922222 | N55: =SUMIF('EPL DATA'!$G$1143:$G$1512,$F55,'EPL DATA'!$S$1143:$S$1512)/$X55 -> 1.2711111 | O55: =G55/$B$46 -> 1.8143051 | P55: =H55/$B$48 -> 0.70398436 | Q55: =I55/$B$50 -> 1.3972301 | R55: =J55/$B$52 -> 0.58966153 | S55: =K55/$B$56 -> 1.5940168 | T55: =L55/$B$58 -> 0.71811605 | U55: =M55/$B$60 -> 1.4586177 | V55: =N55/$B$62 -> 0.79715772 | W55: =COUNTIF('EPL DATA'!$F$1143:$F$1512, $F55) -> 19 | X55: =COUNTIF('EPL DATA'!$G$1143:$G$1512, $F55) -> 18
B56: =SUM(K44:K63)/20 -> 1.5951096 | F56: Manchester City | G56: =SUMIF('EPL DATA'!$F$1143:$F$1512,$F56,'EPL DATA'!$Q$1143:$Q$1512)/$W56 -> 2.8888889 | H56: =SUMIF('EPL DATA'!$F$1143:$F$1512,$F56,'EPL DATA'!$R$1143:$R$1512)/$W56 -> 0.72222222 | I56: =SUMIF('EPL DATA'!$G$1143:$G$1512,$F56,'EPL DATA'!$R$1143:$R$1512)/$X56 -> 2.3684211 | J56: =SUMIF('EPL DATA'!$G$1143:$G$1512,$F56,'EPL DATA'!$Q$1143:$Q$1512)/$X56 -> 1.1578947 | K56: =SUMIF('EPL DATA'!$F$1143:$F$1512,$F56,'EPL DATA'!$S$1143:$S$1512)/$W56 -> 2.7583333 | L56: =SUMIF('EPL DATA'!$F$1143:$F$1512,$F56,'EPL DATA'!$T$1143:$T$1512)/$W56 -> 0.83833333 | M56: =SUMIF('EPL DATA'!$G$1143:$G$1512,$F56,'EPL DATA'!$T$1143:$T$1512)/$X56 -> 2.7889474 | N56: =SUMIF('EPL DATA'!$G$1143:$G$1512,$F56,'EPL DATA'!$S$1143:$S$1512)/$X56 -> 1.1952632 | O56: =G56/$B$46 -> 1.9150998 | P56: =H56/$B$48 -> 0.60376436 | Q56: =I56/$B$50 -> 1.9855374 | R56: =J56/$B$52 -> 0.76811173 | S56: =K56/$B$56 -> 1.7292437 | T56: =L56/$B$58 -> 0.61266159 | U56: =M56/$B$60 -> 2.0419448 | V56: =N56/$B$62 -> 0.74959085 | W56: =COUNTIF('EPL DATA'!$F$1143:$F$1512, $F56) -> 18 | X56: =COUNTIF('EPL DATA'!$G$1143:$G$1512, $F56) -> 19
B57: XHome average goal conceded | F57: Manchester United | G57: =SUMIF('EPL DATA'!$F$1143:$F$1512,$F57,'EPL DATA'!$Q$1143:$Q$1512)/$W57 -> 2.1052632 | H57: =SUMIF('EPL DATA'!$F$1143:$F$1512,$F57,'EPL DATA'!$R$1143:$R$1512)/$W57 -> 0.89473684 | I57: =SUMIF('EPL DATA'!$G$1143:$G$1512,$F57,'EPL DATA'!$R$1143:$R$1512)/$X57 -> 1.3333333 | J57: =SUMIF('EPL DATA'!$G$1143:$G$1512,$F57,'EPL DATA'!$Q$1143:$Q$1512)/$X57 -> 1.0555556 | K57: =SUMIF('EPL DATA'!$F$1143:$F$1512,$F57,'EPL DATA'!$S$1143:$S$1512)/$W57 -> 1.8289474 | L57: =SUMIF('EPL DATA'!$F$1143:$F$1512,$F57,'EPL DATA'!$T$1143:$T$1512)/$W57 -> 0.97105263 | M57: =SUMIF('EPL DATA'!$G$1143:$G$1512,$F57,'EPL DATA'!$T$1143:$T$1512)/$X57 -> 1.5716667 | N57: =SUMIF('EPL DATA'!$G$1143:$G$1512,$F57,'EPL DATA'!$S$1143:$S$1512)/$X57 -> 1.1838889 | O57: =G57/$B$46 -> 1.3956193 | P57: =H57/$B$48 -> 0.74798338 | Q57: =I57/$B$50 -> 1.117784 | R57: =J57/$B$52 -> 0.70022306 | S57: =K57/$B$56 -> 1.1465966 | T57: =L57/$B$58 -> 0.70965405 | U57: =M57/$B$60 -> 1.1507053 | V57: =N57/$B$62 -> 0.74245765 | W57: =COUNTIF('EPL DATA'!$F$1143:$F$1512, $F57) -> 19 | X57: =COUNTIF('EPL DATA'!$G$1143:$G$1512, $F57) -> 18
...

Sheet BackTest
AJ1: Model Home | AK1: Model draw | AL1: Model away | AO1: Market Home | AP1: Market Draw | AQ1: Market Away | AS1: Home winning | AT1: Draw winning | AU1: Away winning
R2: 1 | S2: My Model | W2: Total correct | X2: =COUNTIF($W$22:$W$509, $R$2)/COUNT($W$22:$W$509) -> 0.53125 | Z2: Better than Odds | AA2: =COUNTIF($Z$22:$Z$509, $R$2)/COUNT($Z$22:$Z$509) -> 0.29411765 | AF2: Odds Total correct | AG2: =COUNTIF($AF$22:$AF$509, $R$2)/COUNT($AF$22:$AF$509) -> 0.540625 | AJ2: =COUNTIF($AB$22:$AB$509,$R$2)/COUNT($AB$22:$AB$509) -> 0.64383562 | AK2: =COUNTIF($AC$22:$AC$509,$R$2)/COUNT($AC$22:$AC$509) -> 0.26315789 | AL2: =COUNTIF($AD$22:$AD$509,$R$2)/COUNT($AD$22:$AD$509) -> 0.45806452 | AO2: =COUNTIF($AH$22:$AH$509,$R$2)/COUNT($AH$22:$AH$509) -> 0.55609756 | AP2: 0 | AQ2: =COUNTIF($AJ$22:$AJ$509,$R$2)/COUNT($AJ$22:$AJ$509) -> 0.51304348 | AS2: =SUM(AK22:AK509) -> 15.82 | AT2: =SUM(AL22:AL509) -> -0.66 | AU2: =SUM(AM22:AM509) -> 5
B3: Real Goals | C3: 0.3 | R3: 0 | S3: Market | W3: Total correct with fans | X3: =COUNTIF($W$22:$W$352, $R$2)/COUNT($W$22:$W$352) -> 0.51818182 | Z3: Better than Odds with fans | AA3: =COUNTIF($Z$22:$Z$352, $R$2)/COUNT($Z$22:$Z$352) -> 0.29824561 | AF3: Odds Total correct with fans | AG3: =COUNTIF($AF$22:$AF$352, $R$2)/COUNT($AF$22:$AF$352) -> 0.54090909 | AJ3: =COUNTIF($AB$22:$AB$352,$R$2)/COUNT($AB$22:$AB$352) -> 0.62 | AK3: =COUNTIF($AC$22:$AC$352,$R$2)/COUNT($AC$22:$AC$352) -> 0.33333333 | AL3: =COUNTIF($AD$22:$AD$352,$R$2)/COUNT($AD$22:$AD$352) -> 0.44444444 | AO3: =COUNTIF($AH$22:$AH$352,$R$2)/COUNT($AH$22:$AH$352) -> 0.53793103 | AP3: 0 | AQ3: =COUNTIF($AJ$22:$AJ$352,$R$2)/COUNT($AJ$22:$AJ$352) -> 0.54666667 | AS3: =SUM(AK22:AK352) -> 4.16 | AT3: =SUM(AL22:AL352) -> 2.86 | AU3: =SUM(AM22:AM352) -> 2.98
B4: XG | C4: 0.7 | H4: Model Implied Probability | K4: Market odds | N4: Market implied probability
G5: H | H5: D | I5: A | K5: H | L5: D | M5: A | N5: H | O5: D | P5: A | R5: Real Winner | S5: Score | V5: Model Winner | W5: Model Correct | X5: Percentage Correct | Z5: Model V Market | AA5: Percentage Better v Market | AB5: Model Home | AC5: Model Draw | AD5: Model Away | AE5: Odds Winner | AF5: Odds Correct | AG5: Percentage Correct | AH5: Odds Home | AI5: Odds Draw | AJ5: Odds Away | AK5: Home winnings | AL5: Draw winnings | AM5: Away winnings
C6: =D6&E6 -> Leicester CityManchester United | D6: =Games!D6 -> Leicester City | E6: =Games!E6 -> Manchester United | G6: =' Poisson 2018'!I7 -> 0.28141113 | H6: =' Poisson 2018'!J7 -> 0.32866552 | I6: =' Poisson 2018'!K7 -> 0.38992335 | K6: =VLOOKUP(BackTest!C6,'Bet365 Odds'!$D$8:$I$387,4,FALSE) -> 3.36 | L6: =VLOOKUP(BackTest!C6,'Bet365 Odds'!$D$8:$I$387,5,FALSE) -> 4.54 | M6: =VLOOKUP(BackTest!C6,'Bet365 Odds'!$D$8:$I$387,6,FALSE) -> 2.35 | N6: =1/K6 -> 0.29761905 | O6: =1/L6 -> 0.22026432 | P6: =1/M6 -> 0.42553191 | R6: =IF(T6>S6,$P$5,IF(T6=S6,$O$5,$N$5)) -> A | S6: =VLOOKUP(C6,'EPL DATA'!$A$1143:$X$1522,17,FALSE) -> 0 | T6: =VLOOKUP($C6,'EPL DATA'!$A$1143:$X$1522,18,FALSE) -> 2 | V6: =IF(MAX(G6:I6)=G6,$G$5,IF(MAX(G6:I6)=H6,$H$5,$I$5)) -> A | W6: =IF(V6=R6, $R$2,$R$3) -> 1 | X6: =COUNTIF(W6:W15, $R$2)/COUNT(W6:W15) -> 0.5 | Z6: =IF(W6=$R$2, IF(V6=$I$5,IF(P6>I6, $R$3, $R$2), IF(V6=$H$5, IF(O6>H6, $R$3, $R$2), IF(V6=$G$5, IF(N6>G6, $R$3, $R$2),""))), "") -> 0 | AA6: =COUNTIF(Z6:Z15, $R$2)/COUNT(Z6:Z15) -> 0 | AB6: =IF(V6=$G$5, IF(W6=$R$2, 1,0), "") | AC6: =IF(V6=$H$5, IF(W6=$R$2, 1,0), "") | AD6: =IF(V6=$I$5, IF(W6=$R$2, 1,0), "") -> 1 | AE6: =IF(MAX(N6:P6)=N6,$N$5,IF(MAX(N6:P6)=O6,$O$5,$P$5)) -> A | AF6: =IF(AE6=R6, $R$2,$R$3) -> 1 | AG6: =COUNTIF(AF6:AF15, $R$2)/COUNT(AF6:AF15) -> 0.6 | AH6: =IF(AE6=$G$5, IF(AF6=$R$2, 1,0), "") | AI6: =IF(AE6=$H$5, IF(AF6=$R$2, 1,0), "") | AJ6: =IF(AE6=$I$5, IF(AF6=$R$2, 1,0), "") -> 1 | AK6: =IF(AB6=1, K6-1, IF(AB6=0, -1,"")) | AL6: =IF(AC6=1, L6-1, IF(AC6=0, -1,"")) | AM6: =IF(AD6=1, M6-1, IF(AD6=0, -1,"")) -> 1.35
C7: =D7&E7 -> SouthamptonSheffield United | D7: =Games!D7 -> Southampton | E7: =Games!E7 -> Sheffield United | G7: =' Poisson 2018'!I40 -> 0.30255918 | H7: =' Poisson 2018'!J40 -> 0.34329592 | I7: =' Poisson 2018'!K40 -> 0.3541449 | K7: =VLOOKUP(BackTest!C7,'Bet365 Odds'!$D$8:$I$387,4,FALSE) -> 2.25 | L7: =VLOOKUP(BackTest!C7,'Bet365 Odds'!$D$8:$I$387,5,FALSE) -> 3.6 | M7: =VLOOKUP(BackTest!C7,'Bet365 Odds'!$D$8:$I$387,6,FALSE) -> 3.56 | N7: =1/K7 -> 0.44444444 | O7: =1/L7 -> 0.27777778 | P7: =1/M7 -> 0.28089888 | R7: =IF(T7>S7,$P$5,IF(T7=S7,$O$5,$N$5)) -> H | S7: =VLOOKUP(C7,'EPL DATA'!$A$1143:$X$1522,17,FALSE) -> 3 | T7: =VLOOKUP($C7,'EPL DATA'!$A$1143:$X$1522,18,FALSE) -> 1 | V7: =IF(MAX(G7:I7)=G7,$G$5,IF(MAX(G7:I7)=H7,$H$5,$I$5)) -> A | W7: =IF(V7=R7, $R$2,$R$3) -> 0 | Z7: =IF(W7=$R$2, IF(V7=$I$5,IF(P7>I7, $R$3, $R$2), IF(V7=$H$5, IF(O7>H7, $R$3, $R$2), IF(V7=$G$5, IF(N7>G7, $R$3, $R$2),""))), "") | AB7: =IF(V7=$G$5, IF(W7=$R$2, 1,0), "") | AC7: =IF(V7=$H$5, IF(W7=$R$2, 1,0), "") | AD7: =IF(V7=$I$5, IF(W7=$R$2, 1,0), "") -> 0 | AE7: =IF(MAX(N7:P7)=N7,$N$5,IF(MAX(N7:P7)=O7,$O$5,$P$5)) -> H | AF7: =IF(AE7=R7, $R$2,$R$3) -> 1 | AH7: =IF(AE7=$G$5, IF(AF7=$R$2, 1,0), "") -> 1 | AI7: =IF(AE7=$H$5, IF(AF7=$R$2, 1,0), "") | AJ7: =IF(AE7=$I$5, IF(AF7=$R$2, 1,0), "") | AK7: =IF(AB7=1, K7-1, IF(AB7=0, -1,"")) | AL7: =IF(AC7=1, L7-1, IF(AC7=0, -1,"")) | AM7: =IF(AD7=1, M7-1, IF(AD7=0, -1,"")) -> -1
C8: =D8&E8 -> BurnleyBrighton and Hove Albion | D8: =Games!D8 -> Burnley | E8: =Games!E8 -> Brighton and Hove Albion | G8: =' Poisson 2018'!I73 -> 0.37262373 | H8: =' Poisson 2018'!J73 -> 0.31707442 | I8: =' Poisson 2018'!K73 -> 0.31030185 | K8: =VLOOKUP(BackTest!C8,'Bet365 Odds'!$D$8:$I$387,4,FALSE) -> 2.38 | L8: =VLOOKUP(BackTest!C8,'Bet365 Odds'!$D$8:$I$387,5,FALSE) -> 3.65 | M8: =VLOOKUP(BackTest!C8,'Bet365 Odds'!$D$8:$I$387,6,FALSE) -> 3.26 | N8: =1/K8 -> 0.42016807 | O8: =1/L8 -> 0.2739726 | P8: =1/M8 -> 0.30674847 | R8: =IF(T8>S8,$P$5,IF(T8=S8,$O$5,$N$5)) -> A | S8: =VLOOKUP(C8,'EPL DATA'!$A$1143:$X$1522,17,FALSE) -> 1 | T8: =VLOOKUP($C8,'EPL DATA'!$A$1143:$X$1522,18,FALSE) -> 2 | V8: =IF(MAX(G8:I8)=G8,$G$5,IF(MAX(G8:I8)=H8,$H$5,$I$5)) -> H | W8: =IF(V8=R8, $R$2,$R$3) -> 0 | Z8: =IF(W8=$R$2, IF(V8=$I$5,IF(P8>I8, $R$3, $R$2), IF(V8=$H$5, IF(O8>H8, $R$3, $R$2), IF(V8=$G$5, IF(N8>G8, $R$3, $R$2),""))), "") | AB8: =IF(V8=$G$5, IF(W8=$R$2, 1,0), "") -> 0 | AC8: =IF(V8=$H$5, IF(W8=$R$2, 1,0), "") | AD8: =IF(V8=$I$5, IF(W8=$R$2, 1,0), "") | AE8: =IF(MAX(N8:P8)=N8,$N$5,IF(MAX(N8:P8)=O8,$O$5,$P$5)) -> H | AF8: =IF(AE8=R8, $R$2,$R$3) -> 0 | AH8: =IF(AE8=$G$5, IF(AF8=$R$2, 1,0), "") -> 0 | AI8: =IF(AE8=$H$5, IF(AF8=$R$2, 1,0), "") | AJ8: =IF(AE8=$I$5, IF(AF8=$R$2, 1,0), "") | AK8: =IF(AB8=1, K8-1, IF(AB8=0, -1,"")) -> -1 | AL8: =IF(AC8=1, L8-1, IF(AC8=0, -1,"")) | AM8: =IF(AD8=1, M8-1, IF(AD8=0, -1,""))
